Traceback (most recent call last):
  File "C:\Users\Серж\Desktop\TopLiga\TopLiga_webapp\TL_VS_solution\Content_prod\logics\modules\api_request.py", line 97, in PrevCupInfluence
    answer_dict = json.loads(answer)
  File "C:\Users\Серж\AppData\Local\Programs\Python\Python310\lib\json\__init__.py", line 339, in loads
    raise TypeError(f'the JSON object must be str, bytes or bytearray, '
TypeError: the JSON object must be str, bytes or bytearray, not dict

During handling of the above exception, another exception occurred:

Traceback (most recent call last):
  File "C:\Users\Серж\Desktop\TopLiga\TopLiga_webapp\TL_VS_solution\Content_prod\logics\modules\gh_push.py", line 42, in gh_push
    auth = Auth.Token(token)    # using an access token
  File "C:\Users\Серж\AppData\Local\Programs\Python\Python310\lib\site-packages\github\Auth.py", line 117, in __init__
    assert isinstance(token, str)
AssertionError

During handling of the above exception, another exception occurred:

Traceback (most recent call last):
  File "C:\Users\Серж\Desktop\TopLiga\TopLiga_webapp\TL_VS_solution\Content_prod\logics\modules\bug_mail.py", line 25, in bug_mail
    s.login(sender, password)
  File "C:\Users\Серж\AppData\Local\Programs\Python\Python310\lib\smtplib.py", line 739, in login
    (code, resp) = self.auth(
  File "C:\Users\Серж\AppData\Local\Programs\Python\Python310\lib\smtplib.py", line 652, in auth
    authobject(challenge).encode('ascii'), eol='')
AttributeError: 'NoneType' object has no attribute 'encode'

During handling of the above exception, another exception occurred:

Traceback (most recent call last):
  File "C:\Users\Серж\Desktop\TopLiga\TopLiga_webapp\TL_VS_solution\Content_prod\logics\modules\gh_push.py", line 42, in gh_push
    auth = Auth.Token(token)    # using an access token
  File "C:\Users\Серж\AppData\Local\Programs\Python\Python310\lib\site-packages\github\Auth.py", line 117, in __init__
    assert isinstance(token, str)
AssertionError

During handling of the above exception, another exception occurred:

Traceback (most recent call last):
  File "C:\Users\Серж\Desktop\TopLiga\TopLiga_webapp\TL_VS_solution\Content_prod\logics\modules\bug_mail.py", line 25, in bug_mail
    s.login(sender, password)
  File "C:\Users\Серж\AppData\Local\Programs\Python\Python310\lib\smtplib.py", line 739, in login
    (code, resp) = self.auth(
  File "C:\Users\Серж\AppData\Local\Programs\Python\Python310\lib\smtplib.py", line 652, in auth
    authobject(challenge).encode('ascii'), eol='')
AttributeError: 'NoneType' object has no attribute 'encode'

During handling of the above exception, another exception occurred:

Traceback (most recent call last):
  File "C:\Users\Серж\Desktop\TopLiga\TopLiga_webapp\TL_VS_solution\Content_prod\logics\modules\gh_push.py", line 42, in gh_push
    auth = Auth.Token(token)    # using an access token
  File "C:\Users\Серж\AppData\Local\Programs\Python\Python310\lib\site-packages\github\Auth.py", line 117, in __init__
    assert isinstance(token, str)
AssertionError

During handling of the above exception, another exception occurred:

Traceback (most recent call last):
  File "C:\Users\Серж\Desktop\TopLiga\TopLiga_webapp\TL_VS_solution\Content_prod\logics\modules\bug_mail.py", line 25, in bug_mail
    s.login(sender, password)
  File "C:\Users\Серж\AppData\Local\Programs\Python\Python310\lib\smtplib.py", line 739, in login
    (code, resp) = self.auth(
  File "C:\Users\Серж\AppData\Local\Programs\Python\Python310\lib\smtplib.py", line 652, in auth
    authobject(challenge).encode('ascii'), eol='')
AttributeError: 'NoneType' object has no attribute 'encode'

During handling of the above exception, another exception occurred:

Traceback (most recent call last):
  File "C:\Users\Серж\Desktop\TopLiga\TopLiga_webapp\TL_VS_solution\Content_prod\logics\modules\gh_push.py", line 42, in gh_push
    auth = Auth.Token(token)    # using an access token
  File "C:\Users\Серж\AppData\Local\Programs\Python\Python310\lib\site-packages\github\Auth.py", line 117, in __init__
    assert isinstance(token, str)
AssertionError

During handling of the above exception, another exception occurred:

Traceback (most recent call last):
  File "C:\Users\Серж\Desktop\TopLiga\TopLiga_webapp\TL_VS_solution\Content_prod\logics\modules\bug_mail.py", line 25, in bug_mail
    s.login(sender, password)
  File "C:\Users\Серж\AppData\Local\Programs\Python\Python310\lib\smtplib.py", line 739, in login
    (code, resp) = self.auth(
  File "C:\Users\Серж\AppData\Local\Programs\Python\Python310\lib\smtplib.py", line 652, in auth
    authobject(challenge).encode('ascii'), eol='')
AttributeError: 'NoneType' object has no attribute 'encode'

During handling of the above exception, another exception occurred:

Traceback (most recent call last):
  File "C:\Users\Серж\Desktop\TopLiga\TopLiga_webapp\TL_VS_solution\Content_prod\logics\modules\gh_push.py", line 42, in gh_push
    auth = Auth.Token(token)    # using an access token
  File "C:\Users\Серж\AppData\Local\Programs\Python\Python310\lib\site-packages\github\Auth.py", line 117, in __init__
    assert isinstance(token, str)
AssertionError

During handling of the above exception, another exception occurred:

Traceback (most recent call last):
  File "C:\Users\Серж\Desktop\TopLiga\TopLiga_webapp\TL_VS_solution\Content_prod\logics\modules\bug_mail.py", line 25, in bug_mail
    s.login(sender, password)
  File "C:\Users\Серж\AppData\Local\Programs\Python\Python310\lib\smtplib.py", line 739, in login
    (code, resp) = self.auth(
  File "C:\Users\Серж\AppData\Local\Programs\Python\Python310\lib\smtplib.py", line 652, in auth
    authobject(challenge).encode('ascii'), eol='')
AttributeError: 'NoneType' object has no attribute 'encode'

During handling of the above exception, another exception occurred:

Traceback (most recent call last):
  File "C:\Users\Серж\Desktop\TopLiga\TopLiga_webapp\TL_VS_solution\Content_prod\logics\modules\gh_push.py", line 42, in gh_push
    auth = Auth.Token(token)    # using an access token
  File "C:\Users\Серж\AppData\Local\Programs\Python\Python310\lib\site-packages\github\Auth.py", line 117, in __init__
    assert isinstance(token, str)
AssertionError

During handling of the above exception, another exception occurred:

Traceback (most recent call last):
  File "C:\Users\Серж\Desktop\TopLiga\TopLiga_webapp\TL_VS_solution\Content_prod\logics\modules\bug_mail.py", line 25, in bug_mail
    s.login(sender, password)
  File "C:\Users\Серж\AppData\Local\Programs\Python\Python310\lib\smtplib.py", line 739, in login
    (code, resp) = self.auth(
  File "C:\Users\Серж\AppData\Local\Programs\Python\Python310\lib\smtplib.py", line 652, in auth
    authobject(challenge).encode('ascii'), eol='')
AttributeError: 'NoneType' object has no attribute 'encode'

During handling of the above exception, another exception occurred:

Traceback (most recent call last):
  File "C:\Users\Серж\Desktop\TopLiga\TopLiga_webapp\TL_VS_solution\Content_prod\logics\modules\gh_push.py", line 42, in gh_push
    auth = Auth.Token(token)    # using an access token
  File "C:\Users\Серж\AppData\Local\Programs\Python\Python310\lib\site-packages\github\Auth.py", line 117, in __init__
    assert isinstance(token, str)
AssertionError

During handling of the above exception, another exception occurred:

Traceback (most recent call last):
  File "C:\Users\Серж\Desktop\TopLiga\TopLiga_webapp\TL_VS_solution\Content_prod\logics\modules\bug_mail.py", line 25, in bug_mail
    s.login(sender, password)
  File "C:\Users\Серж\AppData\Local\Programs\Python\Python310\lib\smtplib.py", line 739, in login
    (code, resp) = self.auth(
  File "C:\Users\Серж\AppData\Local\Programs\Python\Python310\lib\smtplib.py", line 652, in auth
    authobject(challenge).encode('ascii'), eol='')
AttributeError: 'NoneType' object has no attribute 'encode'

During handling of the above exception, another exception occurred:

Traceback (most recent call last):
  File "C:\Users\Серж\Desktop\TopLiga\TopLiga_webapp\TL_VS_solution\Content_prod\logics\modules\gh_push.py", line 42, in gh_push
    auth = Auth.Token(token)    # using an access token
  File "C:\Users\Серж\AppData\Local\Programs\Python\Python310\lib\site-packages\github\Auth.py", line 117, in __init__
    assert isinstance(token, str)
AssertionError

During handling of the above exception, another exception occurred:

Traceback (most recent call last):
  File "C:\Users\Серж\Desktop\TopLiga\TopLiga_webapp\TL_VS_solution\Content_prod\logics\modules\bug_mail.py", line 25, in bug_mail
    s.login(sender, password)
  File "C:\Users\Серж\AppData\Local\Programs\Python\Python310\lib\smtplib.py", line 739, in login
    (code, resp) = self.auth(
  File "C:\Users\Серж\AppData\Local\Programs\Python\Python310\lib\smtplib.py", line 652, in auth
    authobject(challenge).encode('ascii'), eol='')
AttributeError: 'NoneType' object has no attribute 'encode'

During handling of the above exception, another exception occurred:

Traceback (most recent call last):
  File "C:\Users\Серж\Desktop\TopLiga\TopLiga_webapp\TL_VS_solution\Content_prod\logics\modules\gh_push.py", line 42, in gh_push
    auth = Auth.Token(token)    # using an access token
  File "C:\Users\Серж\AppData\Local\Programs\Python\Python310\lib\site-packages\github\Auth.py", line 117, in __init__
    assert isinstance(token, str)
AssertionError

During handling of the above exception, another exception occurred:

Traceback (most recent call last):
  File "C:\Users\Серж\Desktop\TopLiga\TopLiga_webapp\TL_VS_solution\Content_prod\logics\modules\bug_mail.py", line 25, in bug_mail
    s.login(sender, password)
  File "C:\Users\Серж\AppData\Local\Programs\Python\Python310\lib\smtplib.py", line 739, in login
    (code, resp) = self.auth(
  File "C:\Users\Серж\AppData\Local\Programs\Python\Python310\lib\smtplib.py", line 652, in auth
    authobject(challenge).encode('ascii'), eol='')
AttributeError: 'NoneType' object has no attribute 'encode'

During handling of the above exception, another exception occurred:

Traceback (most recent call last):
  File "C:\Users\Серж\Desktop\TopLiga\TopLiga_webapp\TL_VS_solution\Content_prod\logics\modules\gh_push.py", line 42, in gh_push
    auth = Auth.Token(token)    # using an access token
  File "C:\Users\Серж\AppData\Local\Programs\Python\Python310\lib\site-packages\github\Auth.py", line 117, in __init__
    assert isinstance(token, str)
AssertionError

During handling of the above exception, another exception occurred:

Traceback (most recent call last):
  File "C:\Users\Серж\Desktop\TopLiga\TopLiga_webapp\TL_VS_solution\Content_prod\logics\modules\bug_mail.py", line 25, in bug_mail
    s.login(sender, password)
  File "C:\Users\Серж\AppData\Local\Programs\Python\Python310\lib\smtplib.py", line 739, in login
    (code, resp) = self.auth(
  File "C:\Users\Серж\AppData\Local\Programs\Python\Python310\lib\smtplib.py", line 652, in auth
    authobject(challenge).encode('ascii'), eol='')
AttributeError: 'NoneType' object has no attribute 'encode'

During handling of the above exception, another exception occurred:

Traceback (most recent call last):
  File "C:\Users\Серж\Desktop\TopLiga\TopLiga_webapp\TL_VS_solution\Content_prod\logics\modules\gh_push.py", line 42, in gh_push
    auth = Auth.Token(token)    # using an access token
  File "C:\Users\Серж\AppData\Local\Programs\Python\Python310\lib\site-packages\github\Auth.py", line 117, in __init__
    assert isinstance(token, str)
AssertionError

During handling of the above exception, another exception occurred:

Traceback (most recent call last):
  File "C:\Users\Серж\Desktop\TopLiga\TopLiga_webapp\TL_VS_solution\Content_prod\logics\modules\bug_mail.py", line 25, in bug_mail
    s.login(sender, password)
  File "C:\Users\Серж\AppData\Local\Programs\Python\Python310\lib\smtplib.py", line 739, in login
    (code, resp) = self.auth(
  File "C:\Users\Серж\AppData\Local\Programs\Python\Python310\lib\smtplib.py", line 652, in auth
    authobject(challenge).encode('ascii'), eol='')
AttributeError: 'NoneType' object has no attribute 'encode'

During handling of the above exception, another exception occurred:

Traceback (most recent call last):
  File "C:\Users\Серж\Desktop\TopLiga\TopLiga_webapp\TL_VS_solution\Content_prod\logics\modules\gh_push.py", line 42, in gh_push
    auth = Auth.Token(token)    # using an access token
  File "C:\Users\Серж\AppData\Local\Programs\Python\Python310\lib\site-packages\github\Auth.py", line 117, in __init__
    assert isinstance(token, str)
AssertionError

During handling of the above exception, another exception occurred:

Traceback (most recent call last):
  File "C:\Users\Серж\Desktop\TopLiga\TopLiga_webapp\TL_VS_solution\Content_prod\logics\modules\bug_mail.py", line 25, in bug_mail
    s.login(sender, password)
  File "C:\Users\Серж\AppData\Local\Programs\Python\Python310\lib\smtplib.py", line 739, in login
    (code, resp) = self.auth(
  File "C:\Users\Серж\AppData\Local\Programs\Python\Python310\lib\smtplib.py", line 652, in auth
    authobject(challenge).encode('ascii'), eol='')
AttributeError: 'NoneType' object has no attribute 'encode'

During handling of the above exception, another exception occurred:

Traceback (most recent call last):
  File "C:\Users\Серж\Desktop\TopLiga\TopLiga_webapp\TL_VS_solution\Content_prod\logics\modules\gh_push.py", line 42, in gh_push
    auth = Auth.Token(token)    # using an access token
  File "C:\Users\Серж\AppData\Local\Programs\Python\Python310\lib\site-packages\github\Auth.py", line 117, in __init__
    assert isinstance(token, str)
AssertionError

During handling of the above exception, another exception occurred:

Traceback (most recent call last):
  File "C:\Users\Серж\Desktop\TopLiga\TopLiga_webapp\TL_VS_solution\Content_prod\logics\modules\bug_mail.py", line 25, in bug_mail
    s.login(sender, password)
  File "C:\Users\Серж\AppData\Local\Programs\Python\Python310\lib\smtplib.py", line 739, in login
    (code, resp) = self.auth(
  File "C:\Users\Серж\AppData\Local\Programs\Python\Python310\lib\smtplib.py", line 652, in auth
    authobject(challenge).encode('ascii'), eol='')
AttributeError: 'NoneType' object has no attribute 'encode'

During handling of the above exception, another exception occurred:

Traceback (most recent call last):
  File "C:\Users\Серж\Desktop\TopLiga\TopLiga_webapp\TL_VS_solution\Content_prod\logics\modules\gh_push.py", line 42, in gh_push
    auth = Auth.Token(token)    # using an access token
  File "C:\Users\Серж\AppData\Local\Programs\Python\Python310\lib\site-packages\github\Auth.py", line 117, in __init__
    assert isinstance(token, str)
AssertionError

During handling of the above exception, another exception occurred:

Traceback (most recent call last):
  File "C:\Users\Серж\Desktop\TopLiga\TopLiga_webapp\TL_VS_solution\Content_prod\logics\modules\bug_mail.py", line 25, in bug_mail
    s.login(sender, password)
  File "C:\Users\Серж\AppData\Local\Programs\Python\Python310\lib\smtplib.py", line 739, in login
    (code, resp) = self.auth(
  File "C:\Users\Серж\AppData\Local\Programs\Python\Python310\lib\smtplib.py", line 652, in auth
    authobject(challenge).encode('ascii'), eol='')
AttributeError: 'NoneType' object has no attribute 'encode'

During handling of the above exception, another exception occurred:

Traceback (most recent call last):
  File "C:\Users\Серж\Desktop\TopLiga\TopLiga_webapp\TL_VS_solution\Content_prod\logics\modules\gh_push.py", line 42, in gh_push
    auth = Auth.Token(token)    # using an access token
  File "C:\Users\Серж\AppData\Local\Programs\Python\Python310\lib\site-packages\github\Auth.py", line 117, in __init__
    assert isinstance(token, str)
AssertionError

During handling of the above exception, another exception occurred:

Traceback (most recent call last):
  File "C:\Users\Серж\Desktop\TopLiga\TopLiga_webapp\TL_VS_solution\Content_prod\logics\modules\bug_mail.py", line 25, in bug_mail
    s.login(sender, password)
  File "C:\Users\Серж\AppData\Local\Programs\Python\Python310\lib\smtplib.py", line 739, in login
    (code, resp) = self.auth(
  File "C:\Users\Серж\AppData\Local\Programs\Python\Python310\lib\smtplib.py", line 652, in auth
    authobject(challenge).encode('ascii'), eol='')
AttributeError: 'NoneType' object has no attribute 'encode'

During handling of the above exception, another exception occurred:

Traceback (most recent call last):
  File "C:\Users\Серж\Desktop\TopLiga\TopLiga_webapp\TL_VS_solution\Content_prod\logics\modules\gh_push.py", line 42, in gh_push
    auth = Auth.Token(token)    # using an access token
  File "C:\Users\Серж\AppData\Local\Programs\Python\Python310\lib\site-packages\github\Auth.py", line 117, in __init__
    assert isinstance(token, str)
AssertionError

During handling of the above exception, another exception occurred:

Traceback (most recent call last):
  File "C:\Users\Серж\Desktop\TopLiga\TopLiga_webapp\TL_VS_solution\Content_prod\logics\modules\bug_mail.py", line 25, in bug_mail
    s.login(sender, password)
  File "C:\Users\Серж\AppData\Local\Programs\Python\Python310\lib\smtplib.py", line 739, in login
    (code, resp) = self.auth(
  File "C:\Users\Серж\AppData\Local\Programs\Python\Python310\lib\smtplib.py", line 652, in auth
    authobject(challenge).encode('ascii'), eol='')
AttributeError: 'NoneType' object has no attribute 'encode'

During handling of the above exception, another exception occurred:

Traceback (most recent call last):
  File "C:\Users\Серж\Desktop\TopLiga\TopLiga_webapp\TL_VS_solution\Content_prod\logics\modules\gh_push.py", line 42, in gh_push
    auth = Auth.Token(token)    # using an access token
  File "C:\Users\Серж\AppData\Local\Programs\Python\Python310\lib\site-packages\github\Auth.py", line 117, in __init__
    assert isinstance(token, str)
AssertionError

During handling of the above exception, another exception occurred:

Traceback (most recent call last):
  File "C:\Users\Серж\Desktop\TopLiga\TopLiga_webapp\TL_VS_solution\Content_prod\logics\modules\bug_mail.py", line 25, in bug_mail
    s.login(sender, password)
  File "C:\Users\Серж\AppData\Local\Programs\Python\Python310\lib\smtplib.py", line 739, in login
    (code, resp) = self.auth(
  File "C:\Users\Серж\AppData\Local\Programs\Python\Python310\lib\smtplib.py", line 652, in auth
    authobject(challenge).encode('ascii'), eol='')
AttributeError: 'NoneType' object has no attribute 'encode'

During handling of the above exception, another exception occurred:

Traceback (most recent call last):
  File "C:\Users\Серж\Desktop\TopLiga\TopLiga_webapp\TL_VS_solution\Content_prod\logics\modules\gh_push.py", line 42, in gh_push
    auth = Auth.Token(token)    # using an access token
  File "C:\Users\Серж\AppData\Local\Programs\Python\Python310\lib\site-packages\github\Auth.py", line 117, in __init__
    assert isinstance(token, str)
AssertionError

During handling of the above exception, another exception occurred:

Traceback (most recent call last):
  File "C:\Users\Серж\Desktop\TopLiga\TopLiga_webapp\TL_VS_solution\Content_prod\logics\modules\bug_mail.py", line 25, in bug_mail
    s.login(sender, password)
  File "C:\Users\Серж\AppData\Local\Programs\Python\Python310\lib\smtplib.py", line 739, in login
    (code, resp) = self.auth(
  File "C:\Users\Серж\AppData\Local\Programs\Python\Python310\lib\smtplib.py", line 652, in auth
    authobject(challenge).encode('ascii'), eol='')
AttributeError: 'NoneType' object has no attribute 'encode'

During handling of the above exception, another exception occurred:

Traceback (most recent call last):
  File "C:\Users\Серж\Desktop\TopLiga\TopLiga_webapp\TL_VS_solution\Content_prod\logics\modules\gh_push.py", line 42, in gh_push
    auth = Auth.Token(token)    # using an access token
  File "C:\Users\Серж\AppData\Local\Programs\Python\Python310\lib\site-packages\github\Auth.py", line 117, in __init__
    assert isinstance(token, str)
AssertionError

During handling of the above exception, another exception occurred:

Traceback (most recent call last):
  File "C:\Users\Серж\Desktop\TopLiga\TopLiga_webapp\TL_VS_solution\Content_prod\logics\modules\bug_mail.py", line 25, in bug_mail
    s.login(sender, password)
  File "C:\Users\Серж\AppData\Local\Programs\Python\Python310\lib\smtplib.py", line 739, in login
    (code, resp) = self.auth(
  File "C:\Users\Серж\AppData\Local\Programs\Python\Python310\lib\smtplib.py", line 652, in auth
    authobject(challenge).encode('ascii'), eol='')
AttributeError: 'NoneType' object has no attribute 'encode'

During handling of the above exception, another exception occurred:

Traceback (most recent call last):
  File "C:\Users\Серж\Desktop\TopLiga\TopLiga_webapp\TL_VS_solution\Content_prod\logics\modules\gh_push.py", line 42, in gh_push
    auth = Auth.Token(token)    # using an access token
  File "C:\Users\Серж\AppData\Local\Programs\Python\Python310\lib\site-packages\github\Auth.py", line 117, in __init__
    assert isinstance(token, str)
AssertionError

During handling of the above exception, another exception occurred:

Traceback (most recent call last):
  File "C:\Users\Серж\Desktop\TopLiga\TopLiga_webapp\TL_VS_solution\Content_prod\logics\modules\bug_mail.py", line 25, in bug_mail
    s.login(sender, password)
  File "C:\Users\Серж\AppData\Local\Programs\Python\Python310\lib\smtplib.py", line 739, in login
    (code, resp) = self.auth(
  File "C:\Users\Серж\AppData\Local\Programs\Python\Python310\lib\smtplib.py", line 652, in auth
    authobject(challenge).encode('ascii'), eol='')
AttributeError: 'NoneType' object has no attribute 'encode'

During handling of the above exception, another exception occurred:

Traceback (most recent call last):
  File "C:\Users\Серж\Desktop\TopLiga\TopLiga_webapp\TL_VS_solution\Content_prod\logics\modules\gh_push.py", line 42, in gh_push
    auth = Auth.Token(token)    # using an access token
  File "C:\Users\Серж\AppData\Local\Programs\Python\Python310\lib\site-packages\github\Auth.py", line 117, in __init__
    assert isinstance(token, str)
AssertionError

During handling of the above exception, another exception occurred:

Traceback (most recent call last):
  File "C:\Users\Серж\Desktop\TopLiga\TopLiga_webapp\TL_VS_solution\Content_prod\logics\modules\bug_mail.py", line 25, in bug_mail
    s.login(sender, password)
  File "C:\Users\Серж\AppData\Local\Programs\Python\Python310\lib\smtplib.py", line 739, in login
    (code, resp) = self.auth(
  File "C:\Users\Серж\AppData\Local\Programs\Python\Python310\lib\smtplib.py", line 652, in auth
    authobject(challenge).encode('ascii'), eol='')
AttributeError: 'NoneType' object has no attribute 'encode'

During handling of the above exception, another exception occurred:

Traceback (most recent call last):
  File "C:\Users\Серж\Desktop\TopLiga\TopLiga_webapp\TL_VS_solution\Content_prod\logics\modules\gh_push.py", line 42, in gh_push
    auth = Auth.Token(token)    # using an access token
  File "C:\Users\Серж\AppData\Local\Programs\Python\Python310\lib\site-packages\github\Auth.py", line 117, in __init__
    assert isinstance(token, str)
AssertionError

During handling of the above exception, another exception occurred:

Traceback (most recent call last):
  File "C:\Users\Серж\Desktop\TopLiga\TopLiga_webapp\TL_VS_solution\Content_prod\logics\modules\bug_mail.py", line 25, in bug_mail
    s.login(sender, password)
  File "C:\Users\Серж\AppData\Local\Programs\Python\Python310\lib\smtplib.py", line 739, in login
    (code, resp) = self.auth(
  File "C:\Users\Серж\AppData\Local\Programs\Python\Python310\lib\smtplib.py", line 652, in auth
    authobject(challenge).encode('ascii'), eol='')
AttributeError: 'NoneType' object has no attribute 'encode'

During handling of the above exception, another exception occurred:

Traceback (most recent call last):
  File "C:\Users\Серж\Desktop\TopLiga\TopLiga_webapp\TL_VS_solution\Content_prod\logics\modules\gh_push.py", line 42, in gh_push
    auth = Auth.Token(token)    # using an access token
  File "C:\Users\Серж\AppData\Local\Programs\Python\Python310\lib\site-packages\github\Auth.py", line 117, in __init__
    assert isinstance(token, str)
AssertionError

During handling of the above exception, another exception occurred:

Traceback (most recent call last):
  File "C:\Users\Серж\Desktop\TopLiga\TopLiga_webapp\TL_VS_solution\Content_prod\logics\modules\bug_mail.py", line 25, in bug_mail
    s.login(sender, password)
  File "C:\Users\Серж\AppData\Local\Programs\Python\Python310\lib\smtplib.py", line 739, in login
    (code, resp) = self.auth(
  File "C:\Users\Серж\AppData\Local\Programs\Python\Python310\lib\smtplib.py", line 652, in auth
    authobject(challenge).encode('ascii'), eol='')
AttributeError: 'NoneType' object has no attribute 'encode'

During handling of the above exception, another exception occurred:

Traceback (most recent call last):
  File "C:\Users\Серж\Desktop\TopLiga\TopLiga_webapp\TL_VS_solution\Content_prod\logics\modules\gh_push.py", line 42, in gh_push
    auth = Auth.Token(token)    # using an access token
  File "C:\Users\Серж\AppData\Local\Programs\Python\Python310\lib\site-packages\github\Auth.py", line 117, in __init__
    assert isinstance(token, str)
AssertionError

During handling of the above exception, another exception occurred:

Traceback (most recent call last):
  File "C:\Users\Серж\Desktop\TopLiga\TopLiga_webapp\TL_VS_solution\Content_prod\logics\modules\bug_mail.py", line 25, in bug_mail
    s.login(sender, password)
  File "C:\Users\Серж\AppData\Local\Programs\Python\Python310\lib\smtplib.py", line 739, in login
    (code, resp) = self.auth(
  File "C:\Users\Серж\AppData\Local\Programs\Python\Python310\lib\smtplib.py", line 652, in auth
    authobject(challenge).encode('ascii'), eol='')
AttributeError: 'NoneType' object has no attribute 'encode'

During handling of the above exception, another exception occurred:

Traceback (most recent call last):
  File "C:\Users\Серж\Desktop\TopLiga\TopLiga_webapp\TL_VS_solution\Content_prod\logics\modules\gh_push.py", line 42, in gh_push
    auth = Auth.Token(token)    # using an access token
  File "C:\Users\Серж\AppData\Local\Programs\Python\Python310\lib\site-packages\github\Auth.py", line 117, in __init__
    assert isinstance(token, str)
AssertionError

During handling of the above exception, another exception occurred:

Traceback (most recent call last):
  File "C:\Users\Серж\Desktop\TopLiga\TopLiga_webapp\TL_VS_solution\Content_prod\logics\modules\bug_mail.py", line 25, in bug_mail
    s.login(sender, password)
  File "C:\Users\Серж\AppData\Local\Programs\Python\Python310\lib\smtplib.py", line 739, in login
    (code, resp) = self.auth(
  File "C:\Users\Серж\AppData\Local\Programs\Python\Python310\lib\smtplib.py", line 652, in auth
    authobject(challenge).encode('ascii'), eol='')
AttributeError: 'NoneType' object has no attribute 'encode'

During handling of the above exception, another exception occurred:

Traceback (most recent call last):
  File "C:\Users\Серж\Desktop\TopLiga\TopLiga_webapp\TL_VS_solution\Content_prod\logics\modules\gh_push.py", line 42, in gh_push
    auth = Auth.Token(token)    # using an access token
  File "C:\Users\Серж\AppData\Local\Programs\Python\Python310\lib\site-packages\github\Auth.py", line 117, in __init__
    assert isinstance(token, str)
AssertionError

During handling of the above exception, another exception occurred:

Traceback (most recent call last):
  File "C:\Users\Серж\Desktop\TopLiga\TopLiga_webapp\TL_VS_solution\Content_prod\logics\modules\bug_mail.py", line 25, in bug_mail
    s.login(sender, password)
  File "C:\Users\Серж\AppData\Local\Programs\Python\Python310\lib\smtplib.py", line 739, in login
    (code, resp) = self.auth(
  File "C:\Users\Серж\AppData\Local\Programs\Python\Python310\lib\smtplib.py", line 652, in auth
    authobject(challenge).encode('ascii'), eol='')
AttributeError: 'NoneType' object has no attribute 'encode'

During handling of the above exception, another exception occurred:

Traceback (most recent call last):
  File "C:\Users\Серж\Desktop\TopLiga\TopLiga_webapp\TL_VS_solution\Content_prod\logics\modules\gh_push.py", line 42, in gh_push
    auth = Auth.Token(token)    # using an access token
  File "C:\Users\Серж\AppData\Local\Programs\Python\Python310\lib\site-packages\github\Auth.py", line 117, in __init__
    assert isinstance(token, str)
AssertionError

During handling of the above exception, another exception occurred:

Traceback (most recent call last):
  File "C:\Users\Серж\Desktop\TopLiga\TopLiga_webapp\TL_VS_solution\Content_prod\logics\modules\bug_mail.py", line 25, in bug_mail
    s.login(sender, password)
  File "C:\Users\Серж\AppData\Local\Programs\Python\Python310\lib\smtplib.py", line 739, in login
    (code, resp) = self.auth(
  File "C:\Users\Серж\AppData\Local\Programs\Python\Python310\lib\smtplib.py", line 652, in auth
    authobject(challenge).encode('ascii'), eol='')
AttributeError: 'NoneType' object has no attribute 'encode'

During handling of the above exception, another exception occurred:

Traceback (most recent call last):
  File "C:\Users\Серж\Desktop\TopLiga\TopLiga_webapp\TL_VS_solution\Content_prod\logics\modules\gh_push.py", line 42, in gh_push
    auth = Auth.Token(token)    # using an access token
  File "C:\Users\Серж\AppData\Local\Programs\Python\Python310\lib\site-packages\github\Auth.py", line 117, in __init__
    assert isinstance(token, str)
AssertionError

During handling of the above exception, another exception occurred:

Traceback (most recent call last):
  File "C:\Users\Серж\Desktop\TopLiga\TopLiga_webapp\TL_VS_solution\Content_prod\logics\modules\bug_mail.py", line 25, in bug_mail
    s.login(sender, password)
  File "C:\Users\Серж\AppData\Local\Programs\Python\Python310\lib\smtplib.py", line 739, in login
    (code, resp) = self.auth(
  File "C:\Users\Серж\AppData\Local\Programs\Python\Python310\lib\smtplib.py", line 652, in auth
    authobject(challenge).encode('ascii'), eol='')
AttributeError: 'NoneType' object has no attribute 'encode'

During handling of the above exception, another exception occurred:

Traceback (most recent call last):
  File "C:\Users\Серж\Desktop\TopLiga\TopLiga_webapp\TL_VS_solution\Content_prod\logics\modules\gh_push.py", line 42, in gh_push
    auth = Auth.Token(token)    # using an access token
  File "C:\Users\Серж\AppData\Local\Programs\Python\Python310\lib\site-packages\github\Auth.py", line 117, in __init__
    assert isinstance(token, str)
AssertionError

During handling of the above exception, another exception occurred:

Traceback (most recent call last):
  File "C:\Users\Серж\Desktop\TopLiga\TopLiga_webapp\TL_VS_solution\Content_prod\logics\modules\bug_mail.py", line 25, in bug_mail
    s.login(sender, password)
  File "C:\Users\Серж\AppData\Local\Programs\Python\Python310\lib\smtplib.py", line 739, in login
    (code, resp) = self.auth(
  File "C:\Users\Серж\AppData\Local\Programs\Python\Python310\lib\smtplib.py", line 652, in auth
    authobject(challenge).encode('ascii'), eol='')
AttributeError: 'NoneType' object has no attribute 'encode'

During handling of the above exception, another exception occurred:

Traceback (most recent call last):
  File "C:\Users\Серж\Desktop\TopLiga\TopLiga_webapp\TL_VS_solution\Content_prod\logics\modules\gh_push.py", line 42, in gh_push
    auth = Auth.Token(token)    # using an access token
  File "C:\Users\Серж\AppData\Local\Programs\Python\Python310\lib\site-packages\github\Auth.py", line 117, in __init__
    assert isinstance(token, str)
AssertionError

During handling of the above exception, another exception occurred:

Traceback (most recent call last):
  File "C:\Users\Серж\Desktop\TopLiga\TopLiga_webapp\TL_VS_solution\Content_prod\logics\modules\bug_mail.py", line 25, in bug_mail
    s.login(sender, password)
  File "C:\Users\Серж\AppData\Local\Programs\Python\Python310\lib\smtplib.py", line 739, in login
    (code, resp) = self.auth(
  File "C:\Users\Серж\AppData\Local\Programs\Python\Python310\lib\smtplib.py", line 652, in auth
    authobject(challenge).encode('ascii'), eol='')
AttributeError: 'NoneType' object has no attribute 'encode'

During handling of the above exception, another exception occurred:

Traceback (most recent call last):
  File "C:\Users\Серж\Desktop\TopLiga\TopLiga_webapp\TL_VS_solution\Content_prod\logics\modules\gh_push.py", line 42, in gh_push
    auth = Auth.Token(token)    # using an access token
  File "C:\Users\Серж\AppData\Local\Programs\Python\Python310\lib\site-packages\github\Auth.py", line 117, in __init__
    assert isinstance(token, str)
AssertionError

During handling of the above exception, another exception occurred:

Traceback (most recent call last):
  File "C:\Users\Серж\Desktop\TopLiga\TopLiga_webapp\TL_VS_solution\Content_prod\logics\modules\bug_mail.py", line 25, in bug_mail
    s.login(sender, password)
  File "C:\Users\Серж\AppData\Local\Programs\Python\Python310\lib\smtplib.py", line 739, in login
    (code, resp) = self.auth(
  File "C:\Users\Серж\AppData\Local\Programs\Python\Python310\lib\smtplib.py", line 652, in auth
    authobject(challenge).encode('ascii'), eol='')
AttributeError: 'NoneType' object has no attribute 'encode'

During handling of the above exception, another exception occurred:

Traceback (most recent call last):
  File "C:\Users\Серж\Desktop\TopLiga\TopLiga_webapp\TL_VS_solution\Content_prod\logics\modules\gh_push.py", line 42, in gh_push
    auth = Auth.Token(token)    # using an access token
  File "C:\Users\Серж\AppData\Local\Programs\Python\Python310\lib\site-packages\github\Auth.py", line 117, in __init__
    assert isinstance(token, str)
AssertionError

During handling of the above exception, another exception occurred:

Traceback (most recent call last):
  File "C:\Users\Серж\Desktop\TopLiga\TopLiga_webapp\TL_VS_solution\Content_prod\logics\modules\bug_mail.py", line 25, in bug_mail
    s.login(sender, password)
  File "C:\Users\Серж\AppData\Local\Programs\Python\Python310\lib\smtplib.py", line 739, in login
    (code, resp) = self.auth(
  File "C:\Users\Серж\AppData\Local\Programs\Python\Python310\lib\smtplib.py", line 652, in auth
    authobject(challenge).encode('ascii'), eol='')
AttributeError: 'NoneType' object has no attribute 'encode'

During handling of the above exception, another exception occurred:

Traceback (most recent call last):
  File "C:\Users\Серж\Desktop\TopLiga\TopLiga_webapp\TL_VS_solution\Content_prod\logics\modules\gh_push.py", line 42, in gh_push
    auth = Auth.Token(token)    # using an access token
  File "C:\Users\Серж\AppData\Local\Programs\Python\Python310\lib\site-packages\github\Auth.py", line 117, in __init__
    assert isinstance(token, str)
AssertionError

During handling of the above exception, another exception occurred:

Traceback (most recent call last):
  File "C:\Users\Серж\Desktop\TopLiga\TopLiga_webapp\TL_VS_solution\Content_prod\logics\modules\bug_mail.py", line 25, in bug_mail
    s.login(sender, password)
  File "C:\Users\Серж\AppData\Local\Programs\Python\Python310\lib\smtplib.py", line 739, in login
    (code, resp) = self.auth(
  File "C:\Users\Серж\AppData\Local\Programs\Python\Python310\lib\smtplib.py", line 652, in auth
    authobject(challenge).encode('ascii'), eol='')
AttributeError: 'NoneType' object has no attribute 'encode'

During handling of the above exception, another exception occurred:

Traceback (most recent call last):
  File "C:\Users\Серж\Desktop\TopLiga\TopLiga_webapp\TL_VS_solution\Content_prod\logics\modules\gh_push.py", line 42, in gh_push
    auth = Auth.Token(token)    # using an access token
  File "C:\Users\Серж\AppData\Local\Programs\Python\Python310\lib\site-packages\github\Auth.py", line 117, in __init__
    assert isinstance(token, str)
AssertionError

During handling of the above exception, another exception occurred:

Traceback (most recent call last):
  File "C:\Users\Серж\Desktop\TopLiga\TopLiga_webapp\TL_VS_solution\Content_prod\logics\modules\bug_mail.py", line 25, in bug_mail
    s.login(sender, password)
  File "C:\Users\Серж\AppData\Local\Programs\Python\Python310\lib\smtplib.py", line 739, in login
    (code, resp) = self.auth(
  File "C:\Users\Серж\AppData\Local\Programs\Python\Python310\lib\smtplib.py", line 652, in auth
    authobject(challenge).encode('ascii'), eol='')
AttributeError: 'NoneType' object has no attribute 'encode'

During handling of the above exception, another exception occurred:

Traceback (most recent call last):
  File "C:\Users\Серж\Desktop\TopLiga\TopLiga_webapp\TL_VS_solution\Content_prod\logics\modules\gh_push.py", line 42, in gh_push
    auth = Auth.Token(token)    # using an access token
  File "C:\Users\Серж\AppData\Local\Programs\Python\Python310\lib\site-packages\github\Auth.py", line 117, in __init__
    assert isinstance(token, str)
AssertionError

During handling of the above exception, another exception occurred:

Traceback (most recent call last):
  File "C:\Users\Серж\Desktop\TopLiga\TopLiga_webapp\TL_VS_solution\Content_prod\logics\modules\bug_mail.py", line 25, in bug_mail
    s.login(sender, password)
  File "C:\Users\Серж\AppData\Local\Programs\Python\Python310\lib\smtplib.py", line 739, in login
    (code, resp) = self.auth(
  File "C:\Users\Серж\AppData\Local\Programs\Python\Python310\lib\smtplib.py", line 652, in auth
    authobject(challenge).encode('ascii'), eol='')
AttributeError: 'NoneType' object has no attribute 'encode'

During handling of the above exception, another exception occurred:

Traceback (most recent call last):
  File "C:\Users\Серж\Desktop\TopLiga\TopLiga_webapp\TL_VS_solution\Content_prod\logics\modules\gh_push.py", line 42, in gh_push
    auth = Auth.Token(token)    # using an access token
  File "C:\Users\Серж\AppData\Local\Programs\Python\Python310\lib\site-packages\github\Auth.py", line 117, in __init__
    assert isinstance(token, str)
AssertionError

During handling of the above exception, another exception occurred:

Traceback (most recent call last):
  File "C:\Users\Серж\Desktop\TopLiga\TopLiga_webapp\TL_VS_solution\Content_prod\logics\modules\bug_mail.py", line 25, in bug_mail
    s.login(sender, password)
  File "C:\Users\Серж\AppData\Local\Programs\Python\Python310\lib\smtplib.py", line 739, in login
    (code, resp) = self.auth(
  File "C:\Users\Серж\AppData\Local\Programs\Python\Python310\lib\smtplib.py", line 652, in auth
    authobject(challenge).encode('ascii'), eol='')
AttributeError: 'NoneType' object has no attribute 'encode'

During handling of the above exception, another exception occurred:

Traceback (most recent call last):
  File "C:\Users\Серж\Desktop\TopLiga\TopLiga_webapp\TL_VS_solution\Content_prod\logics\modules\gh_push.py", line 42, in gh_push
    auth = Auth.Token(token)    # using an access token
  File "C:\Users\Серж\AppData\Local\Programs\Python\Python310\lib\site-packages\github\Auth.py", line 117, in __init__
    assert isinstance(token, str)
AssertionError

During handling of the above exception, another exception occurred:

Traceback (most recent call last):
  File "C:\Users\Серж\Desktop\TopLiga\TopLiga_webapp\TL_VS_solution\Content_prod\logics\modules\bug_mail.py", line 25, in bug_mail
    s.login(sender, password)
  File "C:\Users\Серж\AppData\Local\Programs\Python\Python310\lib\smtplib.py", line 739, in login
    (code, resp) = self.auth(
  File "C:\Users\Серж\AppData\Local\Programs\Python\Python310\lib\smtplib.py", line 652, in auth
    authobject(challenge).encode('ascii'), eol='')
AttributeError: 'NoneType' object has no attribute 'encode'

During handling of the above exception, another exception occurred:

Traceback (most recent call last):
  File "C:\Users\Серж\Desktop\TopLiga\TopLiga_webapp\TL_VS_solution\Content_prod\logics\modules\gh_push.py", line 42, in gh_push
    auth = Auth.Token(token)    # using an access token
  File "C:\Users\Серж\AppData\Local\Programs\Python\Python310\lib\site-packages\github\Auth.py", line 117, in __init__
    assert isinstance(token, str)
AssertionError

During handling of the above exception, another exception occurred:

Traceback (most recent call last):
  File "C:\Users\Серж\Desktop\TopLiga\TopLiga_webapp\TL_VS_solution\Content_prod\logics\modules\bug_mail.py", line 25, in bug_mail
    s.login(sender, password)
  File "C:\Users\Серж\AppData\Local\Programs\Python\Python310\lib\smtplib.py", line 739, in login
    (code, resp) = self.auth(
  File "C:\Users\Серж\AppData\Local\Programs\Python\Python310\lib\smtplib.py", line 652, in auth
    authobject(challenge).encode('ascii'), eol='')
AttributeError: 'NoneType' object has no attribute 'encode'

During handling of the above exception, another exception occurred:

Traceback (most recent call last):
  File "C:\Users\Серж\Desktop\TopLiga\TopLiga_webapp\TL_VS_solution\Content_prod\logics\modules\gh_push.py", line 42, in gh_push
    auth = Auth.Token(token)    # using an access token
  File "C:\Users\Серж\AppData\Local\Programs\Python\Python310\lib\site-packages\github\Auth.py", line 117, in __init__
    assert isinstance(token, str)
AssertionError

During handling of the above exception, another exception occurred:

Traceback (most recent call last):
  File "C:\Users\Серж\Desktop\TopLiga\TopLiga_webapp\TL_VS_solution\Content_prod\logics\modules\bug_mail.py", line 25, in bug_mail
    s.login(sender, password)
  File "C:\Users\Серж\AppData\Local\Programs\Python\Python310\lib\smtplib.py", line 739, in login
    (code, resp) = self.auth(
  File "C:\Users\Серж\AppData\Local\Programs\Python\Python310\lib\smtplib.py", line 652, in auth
    authobject(challenge).encode('ascii'), eol='')
AttributeError: 'NoneType' object has no attribute 'encode'

During handling of the above exception, another exception occurred:

Traceback (most recent call last):
  File "C:\Users\Серж\Desktop\TopLiga\TopLiga_webapp\TL_VS_solution\Content_prod\logics\modules\gh_push.py", line 42, in gh_push
    auth = Auth.Token(token)    # using an access token
  File "C:\Users\Серж\AppData\Local\Programs\Python\Python310\lib\site-packages\github\Auth.py", line 117, in __init__
    assert isinstance(token, str)
AssertionError

During handling of the above exception, another exception occurred:

Traceback (most recent call last):
  File "C:\Users\Серж\Desktop\TopLiga\TopLiga_webapp\TL_VS_solution\Content_prod\logics\modules\bug_mail.py", line 25, in bug_mail
    s.login(sender, password)
  File "C:\Users\Серж\AppData\Local\Programs\Python\Python310\lib\smtplib.py", line 739, in login
    (code, resp) = self.auth(
  File "C:\Users\Серж\AppData\Local\Programs\Python\Python310\lib\smtplib.py", line 652, in auth
    authobject(challenge).encode('ascii'), eol='')
AttributeError: 'NoneType' object has no attribute 'encode'

During handling of the above exception, another exception occurred:

Traceback (most recent call last):
  File "C:\Users\Серж\Desktop\TopLiga\TopLiga_webapp\TL_VS_solution\Content_prod\logics\modules\gh_push.py", line 42, in gh_push
    auth = Auth.Token(token)    # using an access token
  File "C:\Users\Серж\AppData\Local\Programs\Python\Python310\lib\site-packages\github\Auth.py", line 117, in __init__
    assert isinstance(token, str)
AssertionError

During handling of the above exception, another exception occurred:

Traceback (most recent call last):
  File "C:\Users\Серж\Desktop\TopLiga\TopLiga_webapp\TL_VS_solution\Content_prod\logics\modules\bug_mail.py", line 25, in bug_mail
    s.login(sender, password)
  File "C:\Users\Серж\AppData\Local\Programs\Python\Python310\lib\smtplib.py", line 739, in login
    (code, resp) = self.auth(
  File "C:\Users\Серж\AppData\Local\Programs\Python\Python310\lib\smtplib.py", line 652, in auth
    authobject(challenge).encode('ascii'), eol='')
AttributeError: 'NoneType' object has no attribute 'encode'

During handling of the above exception, another exception occurred:

Traceback (most recent call last):
  File "C:\Users\Серж\Desktop\TopLiga\TopLiga_webapp\TL_VS_solution\Content_prod\logics\modules\gh_push.py", line 42, in gh_push
    auth = Auth.Token(token)    # using an access token
  File "C:\Users\Серж\AppData\Local\Programs\Python\Python310\lib\site-packages\github\Auth.py", line 117, in __init__
    assert isinstance(token, str)
AssertionError

During handling of the above exception, another exception occurred:

Traceback (most recent call last):
  File "C:\Users\Серж\Desktop\TopLiga\TopLiga_webapp\TL_VS_solution\Content_prod\logics\modules\bug_mail.py", line 25, in bug_mail
    s.login(sender, password)
  File "C:\Users\Серж\AppData\Local\Programs\Python\Python310\lib\smtplib.py", line 739, in login
    (code, resp) = self.auth(
  File "C:\Users\Серж\AppData\Local\Programs\Python\Python310\lib\smtplib.py", line 652, in auth
    authobject(challenge).encode('ascii'), eol='')
AttributeError: 'NoneType' object has no attribute 'encode'

During handling of the above exception, another exception occurred:

Traceback (most recent call last):
  File "C:\Users\Серж\Desktop\TopLiga\TopLiga_webapp\TL_VS_solution\Content_prod\logics\modules\gh_push.py", line 42, in gh_push
    auth = Auth.Token(token)    # using an access token
  File "C:\Users\Серж\AppData\Local\Programs\Python\Python310\lib\site-packages\github\Auth.py", line 117, in __init__
    assert isinstance(token, str)
AssertionError

During handling of the above exception, another exception occurred:

Traceback (most recent call last):
  File "C:\Users\Серж\Desktop\TopLiga\TopLiga_webapp\TL_VS_solution\Content_prod\logics\modules\bug_mail.py", line 25, in bug_mail
    s.login(sender, password)
  File "C:\Users\Серж\AppData\Local\Programs\Python\Python310\lib\smtplib.py", line 739, in login
    (code, resp) = self.auth(
  File "C:\Users\Серж\AppData\Local\Programs\Python\Python310\lib\smtplib.py", line 652, in auth
    authobject(challenge).encode('ascii'), eol='')
AttributeError: 'NoneType' object has no attribute 'encode'

During handling of the above exception, another exception occurred:

Traceback (most recent call last):
  File "C:\Users\Серж\Desktop\TopLiga\TopLiga_webapp\TL_VS_solution\Content_prod\logics\modules\gh_push.py", line 42, in gh_push
    auth = Auth.Token(token)    # using an access token
  File "C:\Users\Серж\AppData\Local\Programs\Python\Python310\lib\site-packages\github\Auth.py", line 117, in __init__
    assert isinstance(token, str)
AssertionError

During handling of the above exception, another exception occurred:

Traceback (most recent call last):
  File "C:\Users\Серж\Desktop\TopLiga\TopLiga_webapp\TL_VS_solution\Content_prod\logics\modules\bug_mail.py", line 25, in bug_mail
    s.login(sender, password)
  File "C:\Users\Серж\AppData\Local\Programs\Python\Python310\lib\smtplib.py", line 739, in login
    (code, resp) = self.auth(
  File "C:\Users\Серж\AppData\Local\Programs\Python\Python310\lib\smtplib.py", line 652, in auth
    authobject(challenge).encode('ascii'), eol='')
AttributeError: 'NoneType' object has no attribute 'encode'

During handling of the above exception, another exception occurred:

Traceback (most recent call last):
  File "C:\Users\Серж\Desktop\TopLiga\TopLiga_webapp\TL_VS_solution\Content_prod\logics\modules\gh_push.py", line 42, in gh_push
    auth = Auth.Token(token)    # using an access token
  File "C:\Users\Серж\AppData\Local\Programs\Python\Python310\lib\site-packages\github\Auth.py", line 117, in __init__
    assert isinstance(token, str)
AssertionError

During handling of the above exception, another exception occurred:

Traceback (most recent call last):
  File "C:\Users\Серж\Desktop\TopLiga\TopLiga_webapp\TL_VS_solution\Content_prod\logics\modules\bug_mail.py", line 25, in bug_mail
    s.login(sender, password)
  File "C:\Users\Серж\AppData\Local\Programs\Python\Python310\lib\smtplib.py", line 739, in login
    (code, resp) = self.auth(
  File "C:\Users\Серж\AppData\Local\Programs\Python\Python310\lib\smtplib.py", line 652, in auth
    authobject(challenge).encode('ascii'), eol='')
AttributeError: 'NoneType' object has no attribute 'encode'

During handling of the above exception, another exception occurred:

Traceback (most recent call last):
  File "C:\Users\Серж\Desktop\TopLiga\TopLiga_webapp\TL_VS_solution\Content_prod\logics\modules\gh_push.py", line 42, in gh_push
    auth = Auth.Token(token)    # using an access token
  File "C:\Users\Серж\AppData\Local\Programs\Python\Python310\lib\site-packages\github\Auth.py", line 117, in __init__
    assert isinstance(token, str)
AssertionError

During handling of the above exception, another exception occurred:

Traceback (most recent call last):
  File "C:\Users\Серж\Desktop\TopLiga\TopLiga_webapp\TL_VS_solution\Content_prod\logics\modules\bug_mail.py", line 25, in bug_mail
    s.login(sender, password)
  File "C:\Users\Серж\AppData\Local\Programs\Python\Python310\lib\smtplib.py", line 739, in login
    (code, resp) = self.auth(
  File "C:\Users\Серж\AppData\Local\Programs\Python\Python310\lib\smtplib.py", line 652, in auth
    authobject(challenge).encode('ascii'), eol='')
AttributeError: 'NoneType' object has no attribute 'encode'

During handling of the above exception, another exception occurred:

Traceback (most recent call last):
  File "C:\Users\Серж\Desktop\TopLiga\TopLiga_webapp\TL_VS_solution\Content_prod\logics\modules\gh_push.py", line 42, in gh_push
    auth = Auth.Token(token)    # using an access token
  File "C:\Users\Серж\AppData\Local\Programs\Python\Python310\lib\site-packages\github\Auth.py", line 117, in __init__
    assert isinstance(token, str)
AssertionError

During handling of the above exception, another exception occurred:

Traceback (most recent call last):
  File "C:\Users\Серж\Desktop\TopLiga\TopLiga_webapp\TL_VS_solution\Content_prod\logics\modules\bug_mail.py", line 25, in bug_mail
    s.login(sender, password)
  File "C:\Users\Серж\AppData\Local\Programs\Python\Python310\lib\smtplib.py", line 739, in login
    (code, resp) = self.auth(
  File "C:\Users\Серж\AppData\Local\Programs\Python\Python310\lib\smtplib.py", line 652, in auth
    authobject(challenge).encode('ascii'), eol='')
AttributeError: 'NoneType' object has no attribute 'encode'

During handling of the above exception, another exception occurred:

Traceback (most recent call last):
  File "C:\Users\Серж\Desktop\TopLiga\TopLiga_webapp\TL_VS_solution\Content_prod\logics\modules\gh_push.py", line 42, in gh_push
    auth = Auth.Token(token)    # using an access token
  File "C:\Users\Серж\AppData\Local\Programs\Python\Python310\lib\site-packages\github\Auth.py", line 117, in __init__
    assert isinstance(token, str)
AssertionError

During handling of the above exception, another exception occurred:

Traceback (most recent call last):
  File "C:\Users\Серж\Desktop\TopLiga\TopLiga_webapp\TL_VS_solution\Content_prod\logics\modules\bug_mail.py", line 25, in bug_mail
    s.login(sender, password)
  File "C:\Users\Серж\AppData\Local\Programs\Python\Python310\lib\smtplib.py", line 739, in login
    (code, resp) = self.auth(
  File "C:\Users\Серж\AppData\Local\Programs\Python\Python310\lib\smtplib.py", line 652, in auth
    authobject(challenge).encode('ascii'), eol='')
AttributeError: 'NoneType' object has no attribute 'encode'

During handling of the above exception, another exception occurred:

Traceback (most recent call last):
  File "C:\Users\Серж\Desktop\TopLiga\TopLiga_webapp\TL_VS_solution\Content_prod\logics\modules\gh_push.py", line 42, in gh_push
    auth = Auth.Token(token)    # using an access token
  File "C:\Users\Серж\AppData\Local\Programs\Python\Python310\lib\site-packages\github\Auth.py", line 117, in __init__
    assert isinstance(token, str)
AssertionError

During handling of the above exception, another exception occurred:

Traceback (most recent call last):
  File "C:\Users\Серж\Desktop\TopLiga\TopLiga_webapp\TL_VS_solution\Content_prod\logics\modules\bug_mail.py", line 25, in bug_mail
    s.login(sender, password)
  File "C:\Users\Серж\AppData\Local\Programs\Python\Python310\lib\smtplib.py", line 739, in login
    (code, resp) = self.auth(
  File "C:\Users\Серж\AppData\Local\Programs\Python\Python310\lib\smtplib.py", line 652, in auth
    authobject(challenge).encode('ascii'), eol='')
AttributeError: 'NoneType' object has no attribute 'encode'

During handling of the above exception, another exception occurred:

Traceback (most recent call last):
  File "C:\Users\Серж\Desktop\TopLiga\TopLiga_webapp\TL_VS_solution\Content_prod\logics\modules\gh_push.py", line 42, in gh_push
    auth = Auth.Token(token)    # using an access token
  File "C:\Users\Серж\AppData\Local\Programs\Python\Python310\lib\site-packages\github\Auth.py", line 117, in __init__
    assert isinstance(token, str)
AssertionError

During handling of the above exception, another exception occurred:

Traceback (most recent call last):
  File "C:\Users\Серж\Desktop\TopLiga\TopLiga_webapp\TL_VS_solution\Content_prod\logics\modules\bug_mail.py", line 25, in bug_mail
    s.login(sender, password)
  File "C:\Users\Серж\AppData\Local\Programs\Python\Python310\lib\smtplib.py", line 739, in login
    (code, resp) = self.auth(
  File "C:\Users\Серж\AppData\Local\Programs\Python\Python310\lib\smtplib.py", line 652, in auth
    authobject(challenge).encode('ascii'), eol='')
AttributeError: 'NoneType' object has no attribute 'encode'

During handling of the above exception, another exception occurred:

Traceback (most recent call last):
  File "C:\Users\Серж\Desktop\TopLiga\TopLiga_webapp\TL_VS_solution\Content_prod\logics\modules\gh_push.py", line 42, in gh_push
    auth = Auth.Token(token)    # using an access token
  File "C:\Users\Серж\AppData\Local\Programs\Python\Python310\lib\site-packages\github\Auth.py", line 117, in __init__
    assert isinstance(token, str)
AssertionError

During handling of the above exception, another exception occurred:

Traceback (most recent call last):
  File "C:\Users\Серж\Desktop\TopLiga\TopLiga_webapp\TL_VS_solution\Content_prod\logics\modules\bug_mail.py", line 25, in bug_mail
    s.login(sender, password)
  File "C:\Users\Серж\AppData\Local\Programs\Python\Python310\lib\smtplib.py", line 739, in login
    (code, resp) = self.auth(
  File "C:\Users\Серж\AppData\Local\Programs\Python\Python310\lib\smtplib.py", line 652, in auth
    authobject(challenge).encode('ascii'), eol='')
AttributeError: 'NoneType' object has no attribute 'encode'

During handling of the above exception, another exception occurred:

Traceback (most recent call last):
  File "C:\Users\Серж\Desktop\TopLiga\TopLiga_webapp\TL_VS_solution\Content_prod\logics\modules\gh_push.py", line 42, in gh_push
    auth = Auth.Token(token)    # using an access token
  File "C:\Users\Серж\AppData\Local\Programs\Python\Python310\lib\site-packages\github\Auth.py", line 117, in __init__
    assert isinstance(token, str)
AssertionError

During handling of the above exception, another exception occurred:

Traceback (most recent call last):
  File "C:\Users\Серж\Desktop\TopLiga\TopLiga_webapp\TL_VS_solution\Content_prod\logics\modules\bug_mail.py", line 25, in bug_mail
    s.login(sender, password)
  File "C:\Users\Серж\AppData\Local\Programs\Python\Python310\lib\smtplib.py", line 739, in login
    (code, resp) = self.auth(
  File "C:\Users\Серж\AppData\Local\Programs\Python\Python310\lib\smtplib.py", line 652, in auth
    authobject(challenge).encode('ascii'), eol='')
AttributeError: 'NoneType' object has no attribute 'encode'

During handling of the above exception, another exception occurred:

Traceback (most recent call last):
  File "C:\Users\Серж\Desktop\TopLiga\TopLiga_webapp\TL_VS_solution\Content_prod\logics\modules\gh_push.py", line 42, in gh_push
    auth = Auth.Token(token)    # using an access token
  File "C:\Users\Серж\AppData\Local\Programs\Python\Python310\lib\site-packages\github\Auth.py", line 117, in __init__
    assert isinstance(token, str)
AssertionError

During handling of the above exception, another exception occurred:

Traceback (most recent call last):
  File "C:\Users\Серж\Desktop\TopLiga\TopLiga_webapp\TL_VS_solution\Content_prod\logics\modules\bug_mail.py", line 25, in bug_mail
    s.login(sender, password)
  File "C:\Users\Серж\AppData\Local\Programs\Python\Python310\lib\smtplib.py", line 739, in login
    (code, resp) = self.auth(
  File "C:\Users\Серж\AppData\Local\Programs\Python\Python310\lib\smtplib.py", line 652, in auth
    authobject(challenge).encode('ascii'), eol='')
AttributeError: 'NoneType' object has no attribute 'encode'

During handling of the above exception, another exception occurred:

Traceback (most recent call last):
  File "C:\Users\Серж\Desktop\TopLiga\TopLiga_webapp\TL_VS_solution\Content_prod\logics\modules\gh_push.py", line 42, in gh_push
    auth = Auth.Token(token)    # using an access token
  File "C:\Users\Серж\AppData\Local\Programs\Python\Python310\lib\site-packages\github\Auth.py", line 117, in __init__
    assert isinstance(token, str)
AssertionError

During handling of the above exception, another exception occurred:

Traceback (most recent call last):
  File "C:\Users\Серж\Desktop\TopLiga\TopLiga_webapp\TL_VS_solution\Content_prod\logics\modules\bug_mail.py", line 25, in bug_mail
    s.login(sender, password)
  File "C:\Users\Серж\AppData\Local\Programs\Python\Python310\lib\smtplib.py", line 739, in login
    (code, resp) = self.auth(
  File "C:\Users\Серж\AppData\Local\Programs\Python\Python310\lib\smtplib.py", line 652, in auth
    authobject(challenge).encode('ascii'), eol='')
AttributeError: 'NoneType' object has no attribute 'encode'

During handling of the above exception, another exception occurred:

Traceback (most recent call last):
  File "C:\Users\Серж\Desktop\TopLiga\TopLiga_webapp\TL_VS_solution\Content_prod\logics\modules\gh_push.py", line 42, in gh_push
    auth = Auth.Token(token)    # using an access token
  File "C:\Users\Серж\AppData\Local\Programs\Python\Python310\lib\site-packages\github\Auth.py", line 117, in __init__
    assert isinstance(token, str)
AssertionError

During handling of the above exception, another exception occurred:

Traceback (most recent call last):
  File "C:\Users\Серж\Desktop\TopLiga\TopLiga_webapp\TL_VS_solution\Content_prod\logics\modules\bug_mail.py", line 25, in bug_mail
    s.login(sender, password)
  File "C:\Users\Серж\AppData\Local\Programs\Python\Python310\lib\smtplib.py", line 739, in login
    (code, resp) = self.auth(
  File "C:\Users\Серж\AppData\Local\Programs\Python\Python310\lib\smtplib.py", line 652, in auth
    authobject(challenge).encode('ascii'), eol='')
AttributeError: 'NoneType' object has no attribute 'encode'

During handling of the above exception, another exception occurred:

Traceback (most recent call last):
  File "C:\Users\Серж\Desktop\TopLiga\TopLiga_webapp\TL_VS_solution\Content_prod\logics\modules\gh_push.py", line 42, in gh_push
    auth = Auth.Token(token)    # using an access token
  File "C:\Users\Серж\AppData\Local\Programs\Python\Python310\lib\site-packages\github\Auth.py", line 117, in __init__
    assert isinstance(token, str)
AssertionError

During handling of the above exception, another exception occurred:

Traceback (most recent call last):
  File "C:\Users\Серж\Desktop\TopLiga\TopLiga_webapp\TL_VS_solution\Content_prod\logics\modules\bug_mail.py", line 25, in bug_mail
    s.login(sender, password)
  File "C:\Users\Серж\AppData\Local\Programs\Python\Python310\lib\smtplib.py", line 739, in login
    (code, resp) = self.auth(
  File "C:\Users\Серж\AppData\Local\Programs\Python\Python310\lib\smtplib.py", line 652, in auth
    authobject(challenge).encode('ascii'), eol='')
AttributeError: 'NoneType' object has no attribute 'encode'

During handling of the above exception, another exception occurred:

Traceback (most recent call last):
  File "C:\Users\Серж\Desktop\TopLiga\TopLiga_webapp\TL_VS_solution\Content_prod\logics\modules\gh_push.py", line 42, in gh_push
    auth = Auth.Token(token)    # using an access token
  File "C:\Users\Серж\AppData\Local\Programs\Python\Python310\lib\site-packages\github\Auth.py", line 117, in __init__
    assert isinstance(token, str)
AssertionError

During handling of the above exception, another exception occurred:

Traceback (most recent call last):
  File "C:\Users\Серж\Desktop\TopLiga\TopLiga_webapp\TL_VS_solution\Content_prod\logics\modules\bug_mail.py", line 25, in bug_mail
    s.login(sender, password)
  File "C:\Users\Серж\AppData\Local\Programs\Python\Python310\lib\smtplib.py", line 739, in login
    (code, resp) = self.auth(
  File "C:\Users\Серж\AppData\Local\Programs\Python\Python310\lib\smtplib.py", line 652, in auth
    authobject(challenge).encode('ascii'), eol='')
AttributeError: 'NoneType' object has no attribute 'encode'

During handling of the above exception, another exception occurred:

Traceback (most recent call last):
  File "C:\Users\Серж\Desktop\TopLiga\TopLiga_webapp\TL_VS_solution\Content_prod\logics\modules\gh_push.py", line 42, in gh_push
    auth = Auth.Token(token)    # using an access token
  File "C:\Users\Серж\AppData\Local\Programs\Python\Python310\lib\site-packages\github\Auth.py", line 117, in __init__
    assert isinstance(token, str)
AssertionError

During handling of the above exception, another exception occurred:

Traceback (most recent call last):
  File "C:\Users\Серж\Desktop\TopLiga\TopLiga_webapp\TL_VS_solution\Content_prod\logics\modules\bug_mail.py", line 25, in bug_mail
    s.login(sender, password)
  File "C:\Users\Серж\AppData\Local\Programs\Python\Python310\lib\smtplib.py", line 739, in login
    (code, resp) = self.auth(
  File "C:\Users\Серж\AppData\Local\Programs\Python\Python310\lib\smtplib.py", line 652, in auth
    authobject(challenge).encode('ascii'), eol='')
AttributeError: 'NoneType' object has no attribute 'encode'

During handling of the above exception, another exception occurred:

Traceback (most recent call last):
  File "C:\Users\Серж\Desktop\TopLiga\TopLiga_webapp\TL_VS_solution\Content_prod\logics\modules\gh_push.py", line 42, in gh_push
    auth = Auth.Token(token)    # using an access token
  File "C:\Users\Серж\AppData\Local\Programs\Python\Python310\lib\site-packages\github\Auth.py", line 117, in __init__
    assert isinstance(token, str)
AssertionError

During handling of the above exception, another exception occurred:

Traceback (most recent call last):
  File "C:\Users\Серж\Desktop\TopLiga\TopLiga_webapp\TL_VS_solution\Content_prod\logics\modules\bug_mail.py", line 25, in bug_mail
    s.login(sender, password)
  File "C:\Users\Серж\AppData\Local\Programs\Python\Python310\lib\smtplib.py", line 739, in login
    (code, resp) = self.auth(
  File "C:\Users\Серж\AppData\Local\Programs\Python\Python310\lib\smtplib.py", line 652, in auth
    authobject(challenge).encode('ascii'), eol='')
AttributeError: 'NoneType' object has no attribute 'encode'

During handling of the above exception, another exception occurred:

Traceback (most recent call last):
  File "C:\Users\Серж\Desktop\TopLiga\TopLiga_webapp\TL_VS_solution\Content_prod\logics\modules\gh_push.py", line 42, in gh_push
    auth = Auth.Token(token)    # using an access token
  File "C:\Users\Серж\AppData\Local\Programs\Python\Python310\lib\site-packages\github\Auth.py", line 117, in __init__
    assert isinstance(token, str)
AssertionError

During handling of the above exception, another exception occurred:

Traceback (most recent call last):
  File "C:\Users\Серж\Desktop\TopLiga\TopLiga_webapp\TL_VS_solution\Content_prod\logics\modules\bug_mail.py", line 25, in bug_mail
    s.login(sender, password)
  File "C:\Users\Серж\AppData\Local\Programs\Python\Python310\lib\smtplib.py", line 739, in login
    (code, resp) = self.auth(
  File "C:\Users\Серж\AppData\Local\Programs\Python\Python310\lib\smtplib.py", line 652, in auth
    authobject(challenge).encode('ascii'), eol='')
AttributeError: 'NoneType' object has no attribute 'encode'

During handling of the above exception, another exception occurred:

Traceback (most recent call last):
  File "C:\Users\Серж\Desktop\TopLiga\TopLiga_webapp\TL_VS_solution\Content_prod\logics\modules\gh_push.py", line 42, in gh_push
    auth = Auth.Token(token)    # using an access token
  File "C:\Users\Серж\AppData\Local\Programs\Python\Python310\lib\site-packages\github\Auth.py", line 117, in __init__
    assert isinstance(token, str)
AssertionError

During handling of the above exception, another exception occurred:

Traceback (most recent call last):
  File "C:\Users\Серж\Desktop\TopLiga\TopLiga_webapp\TL_VS_solution\Content_prod\logics\modules\bug_mail.py", line 25, in bug_mail
    s.login(sender, password)
  File "C:\Users\Серж\AppData\Local\Programs\Python\Python310\lib\smtplib.py", line 739, in login
    (code, resp) = self.auth(
  File "C:\Users\Серж\AppData\Local\Programs\Python\Python310\lib\smtplib.py", line 652, in auth
    authobject(challenge).encode('ascii'), eol='')
AttributeError: 'NoneType' object has no attribute 'encode'

During handling of the above exception, another exception occurred:

Traceback (most recent call last):
  File "C:\Users\Серж\Desktop\TopLiga\TopLiga_webapp\TL_VS_solution\Content_prod\logics\modules\gh_push.py", line 42, in gh_push
    auth = Auth.Token(token)    # using an access token
  File "C:\Users\Серж\AppData\Local\Programs\Python\Python310\lib\site-packages\github\Auth.py", line 117, in __init__
    assert isinstance(token, str)
AssertionError

During handling of the above exception, another exception occurred:

Traceback (most recent call last):
  File "C:\Users\Серж\Desktop\TopLiga\TopLiga_webapp\TL_VS_solution\Content_prod\logics\modules\bug_mail.py", line 25, in bug_mail
    s.login(sender, password)
  File "C:\Users\Серж\AppData\Local\Programs\Python\Python310\lib\smtplib.py", line 739, in login
    (code, resp) = self.auth(
  File "C:\Users\Серж\AppData\Local\Programs\Python\Python310\lib\smtplib.py", line 652, in auth
    authobject(challenge).encode('ascii'), eol='')
AttributeError: 'NoneType' object has no attribute 'encode'

During handling of the above exception, another exception occurred:

Traceback (most recent call last):
  File "C:\Users\Серж\Desktop\TopLiga\TopLiga_webapp\TL_VS_solution\Content_prod\logics\modules\gh_push.py", line 42, in gh_push
    auth = Auth.Token(token)    # using an access token
  File "C:\Users\Серж\AppData\Local\Programs\Python\Python310\lib\site-packages\github\Auth.py", line 117, in __init__
    assert isinstance(token, str)
AssertionError

During handling of the above exception, another exception occurred:

Traceback (most recent call last):
  File "C:\Users\Серж\Desktop\TopLiga\TopLiga_webapp\TL_VS_solution\Content_prod\logics\modules\bug_mail.py", line 25, in bug_mail
    s.login(sender, password)
  File "C:\Users\Серж\AppData\Local\Programs\Python\Python310\lib\smtplib.py", line 739, in login
    (code, resp) = self.auth(
  File "C:\Users\Серж\AppData\Local\Programs\Python\Python310\lib\smtplib.py", line 652, in auth
    authobject(challenge).encode('ascii'), eol='')
AttributeError: 'NoneType' object has no attribute 'encode'

During handling of the above exception, another exception occurred:

Traceback (most recent call last):
  File "C:\Users\Серж\Desktop\TopLiga\TopLiga_webapp\TL_VS_solution\Content_prod\logics\modules\gh_push.py", line 42, in gh_push
    auth = Auth.Token(token)    # using an access token
  File "C:\Users\Серж\AppData\Local\Programs\Python\Python310\lib\site-packages\github\Auth.py", line 117, in __init__
    assert isinstance(token, str)
AssertionError

During handling of the above exception, another exception occurred:

Traceback (most recent call last):
  File "C:\Users\Серж\Desktop\TopLiga\TopLiga_webapp\TL_VS_solution\Content_prod\logics\modules\bug_mail.py", line 25, in bug_mail
    s.login(sender, password)
  File "C:\Users\Серж\AppData\Local\Programs\Python\Python310\lib\smtplib.py", line 739, in login
    (code, resp) = self.auth(
  File "C:\Users\Серж\AppData\Local\Programs\Python\Python310\lib\smtplib.py", line 652, in auth
    authobject(challenge).encode('ascii'), eol='')
AttributeError: 'NoneType' object has no attribute 'encode'

During handling of the above exception, another exception occurred:

Traceback (most recent call last):
  File "C:\Users\Серж\Desktop\TopLiga\TopLiga_webapp\TL_VS_solution\Content_prod\logics\modules\gh_push.py", line 42, in gh_push
    auth = Auth.Token(token)    # using an access token
  File "C:\Users\Серж\AppData\Local\Programs\Python\Python310\lib\site-packages\github\Auth.py", line 117, in __init__
    assert isinstance(token, str)
AssertionError

During handling of the above exception, another exception occurred:

Traceback (most recent call last):
  File "C:\Users\Серж\Desktop\TopLiga\TopLiga_webapp\TL_VS_solution\Content_prod\logics\modules\bug_mail.py", line 25, in bug_mail
    s.login(sender, password)
  File "C:\Users\Серж\AppData\Local\Programs\Python\Python310\lib\smtplib.py", line 739, in login
    (code, resp) = self.auth(
  File "C:\Users\Серж\AppData\Local\Programs\Python\Python310\lib\smtplib.py", line 652, in auth
    authobject(challenge).encode('ascii'), eol='')
AttributeError: 'NoneType' object has no attribute 'encode'

During handling of the above exception, another exception occurred:

Traceback (most recent call last):
  File "C:\Users\Серж\Desktop\TopLiga\TopLiga_webapp\TL_VS_solution\Content_prod\logics\modules\gh_push.py", line 42, in gh_push
    auth = Auth.Token(token)    # using an access token
  File "C:\Users\Серж\AppData\Local\Programs\Python\Python310\lib\site-packages\github\Auth.py", line 117, in __init__
    assert isinstance(token, str)
AssertionError

During handling of the above exception, another exception occurred:

Traceback (most recent call last):
  File "C:\Users\Серж\Desktop\TopLiga\TopLiga_webapp\TL_VS_solution\Content_prod\logics\modules\bug_mail.py", line 25, in bug_mail
    s.login(sender, password)
  File "C:\Users\Серж\AppData\Local\Programs\Python\Python310\lib\smtplib.py", line 739, in login
    (code, resp) = self.auth(
  File "C:\Users\Серж\AppData\Local\Programs\Python\Python310\lib\smtplib.py", line 652, in auth
    authobject(challenge).encode('ascii'), eol='')
AttributeError: 'NoneType' object has no attribute 'encode'

During handling of the above exception, another exception occurred:

Traceback (most recent call last):
  File "C:\Users\Серж\Desktop\TopLiga\TopLiga_webapp\TL_VS_solution\Content_prod\logics\modules\gh_push.py", line 42, in gh_push
    auth = Auth.Token(token)    # using an access token
  File "C:\Users\Серж\AppData\Local\Programs\Python\Python310\lib\site-packages\github\Auth.py", line 117, in __init__
    assert isinstance(token, str)
AssertionError

During handling of the above exception, another exception occurred:

Traceback (most recent call last):
  File "C:\Users\Серж\Desktop\TopLiga\TopLiga_webapp\TL_VS_solution\Content_prod\logics\modules\bug_mail.py", line 25, in bug_mail
    s.login(sender, password)
  File "C:\Users\Серж\AppData\Local\Programs\Python\Python310\lib\smtplib.py", line 739, in login
    (code, resp) = self.auth(
  File "C:\Users\Серж\AppData\Local\Programs\Python\Python310\lib\smtplib.py", line 652, in auth
    authobject(challenge).encode('ascii'), eol='')
AttributeError: 'NoneType' object has no attribute 'encode'

During handling of the above exception, another exception occurred:

Traceback (most recent call last):
  File "C:\Users\Серж\Desktop\TopLiga\TopLiga_webapp\TL_VS_solution\Content_prod\logics\modules\gh_push.py", line 42, in gh_push
    auth = Auth.Token(token)    # using an access token
  File "C:\Users\Серж\AppData\Local\Programs\Python\Python310\lib\site-packages\github\Auth.py", line 117, in __init__
    assert isinstance(token, str)
AssertionError

During handling of the above exception, another exception occurred:

Traceback (most recent call last):
  File "C:\Users\Серж\Desktop\TopLiga\TopLiga_webapp\TL_VS_solution\Content_prod\logics\modules\bug_mail.py", line 25, in bug_mail
    s.login(sender, password)
  File "C:\Users\Серж\AppData\Local\Programs\Python\Python310\lib\smtplib.py", line 739, in login
    (code, resp) = self.auth(
  File "C:\Users\Серж\AppData\Local\Programs\Python\Python310\lib\smtplib.py", line 652, in auth
    authobject(challenge).encode('ascii'), eol='')
AttributeError: 'NoneType' object has no attribute 'encode'

During handling of the above exception, another exception occurred:

Traceback (most recent call last):
  File "C:\Users\Серж\Desktop\TopLiga\TopLiga_webapp\TL_VS_solution\Content_prod\logics\modules\gh_push.py", line 42, in gh_push
    auth = Auth.Token(token)    # using an access token
  File "C:\Users\Серж\AppData\Local\Programs\Python\Python310\lib\site-packages\github\Auth.py", line 117, in __init__
    assert isinstance(token, str)
AssertionError

During handling of the above exception, another exception occurred:

Traceback (most recent call last):
  File "C:\Users\Серж\Desktop\TopLiga\TopLiga_webapp\TL_VS_solution\Content_prod\logics\modules\bug_mail.py", line 25, in bug_mail
    s.login(sender, password)
  File "C:\Users\Серж\AppData\Local\Programs\Python\Python310\lib\smtplib.py", line 739, in login
    (code, resp) = self.auth(
  File "C:\Users\Серж\AppData\Local\Programs\Python\Python310\lib\smtplib.py", line 652, in auth
    authobject(challenge).encode('ascii'), eol='')
AttributeError: 'NoneType' object has no attribute 'encode'

During handling of the above exception, another exception occurred:

Traceback (most recent call last):
  File "C:\Users\Серж\Desktop\TopLiga\TopLiga_webapp\TL_VS_solution\Content_prod\logics\modules\gh_push.py", line 42, in gh_push
    auth = Auth.Token(token)    # using an access token
  File "C:\Users\Серж\AppData\Local\Programs\Python\Python310\lib\site-packages\github\Auth.py", line 117, in __init__
    assert isinstance(token, str)
AssertionError

During handling of the above exception, another exception occurred:

Traceback (most recent call last):
  File "C:\Users\Серж\Desktop\TopLiga\TopLiga_webapp\TL_VS_solution\Content_prod\logics\modules\bug_mail.py", line 25, in bug_mail
    s.login(sender, password)
  File "C:\Users\Серж\AppData\Local\Programs\Python\Python310\lib\smtplib.py", line 739, in login
    (code, resp) = self.auth(
  File "C:\Users\Серж\AppData\Local\Programs\Python\Python310\lib\smtplib.py", line 652, in auth
    authobject(challenge).encode('ascii'), eol='')
AttributeError: 'NoneType' object has no attribute 'encode'

During handling of the above exception, another exception occurred:

Traceback (most recent call last):
  File "C:\Users\Серж\Desktop\TopLiga\TopLiga_webapp\TL_VS_solution\Content_prod\logics\modules\gh_push.py", line 42, in gh_push
    auth = Auth.Token(token)    # using an access token
  File "C:\Users\Серж\AppData\Local\Programs\Python\Python310\lib\site-packages\github\Auth.py", line 117, in __init__
    assert isinstance(token, str)
AssertionError

During handling of the above exception, another exception occurred:

Traceback (most recent call last):
  File "C:\Users\Серж\Desktop\TopLiga\TopLiga_webapp\TL_VS_solution\Content_prod\logics\modules\bug_mail.py", line 25, in bug_mail
    s.login(sender, password)
  File "C:\Users\Серж\AppData\Local\Programs\Python\Python310\lib\smtplib.py", line 739, in login
    (code, resp) = self.auth(
  File "C:\Users\Серж\AppData\Local\Programs\Python\Python310\lib\smtplib.py", line 652, in auth
    authobject(challenge).encode('ascii'), eol='')
AttributeError: 'NoneType' object has no attribute 'encode'

During handling of the above exception, another exception occurred:

Traceback (most recent call last):
  File "C:\Users\Серж\Desktop\TopLiga\TopLiga_webapp\TL_VS_solution\Content_prod\logics\modules\gh_push.py", line 42, in gh_push
    auth = Auth.Token(token)    # using an access token
  File "C:\Users\Серж\AppData\Local\Programs\Python\Python310\lib\site-packages\github\Auth.py", line 117, in __init__
    assert isinstance(token, str)
AssertionError

During handling of the above exception, another exception occurred:

Traceback (most recent call last):
  File "C:\Users\Серж\Desktop\TopLiga\TopLiga_webapp\TL_VS_solution\Content_prod\logics\modules\bug_mail.py", line 25, in bug_mail
    s.login(sender, password)
  File "C:\Users\Серж\AppData\Local\Programs\Python\Python310\lib\smtplib.py", line 739, in login
    (code, resp) = self.auth(
  File "C:\Users\Серж\AppData\Local\Programs\Python\Python310\lib\smtplib.py", line 652, in auth
    authobject(challenge).encode('ascii'), eol='')
AttributeError: 'NoneType' object has no attribute 'encode'

During handling of the above exception, another exception occurred:

Traceback (most recent call last):
  File "C:\Users\Серж\Desktop\TopLiga\TopLiga_webapp\TL_VS_solution\Content_prod\logics\modules\gh_push.py", line 42, in gh_push
    auth = Auth.Token(token)    # using an access token
  File "C:\Users\Серж\AppData\Local\Programs\Python\Python310\lib\site-packages\github\Auth.py", line 117, in __init__
    assert isinstance(token, str)
AssertionError

During handling of the above exception, another exception occurred:

Traceback (most recent call last):
  File "C:\Users\Серж\Desktop\TopLiga\TopLiga_webapp\TL_VS_solution\Content_prod\logics\modules\bug_mail.py", line 25, in bug_mail
    s.login(sender, password)
  File "C:\Users\Серж\AppData\Local\Programs\Python\Python310\lib\smtplib.py", line 739, in login
    (code, resp) = self.auth(
  File "C:\Users\Серж\AppData\Local\Programs\Python\Python310\lib\smtplib.py", line 652, in auth
    authobject(challenge).encode('ascii'), eol='')
AttributeError: 'NoneType' object has no attribute 'encode'

During handling of the above exception, another exception occurred:

Traceback (most recent call last):
  File "C:\Users\Серж\Desktop\TopLiga\TopLiga_webapp\TL_VS_solution\Content_prod\logics\modules\gh_push.py", line 42, in gh_push
    auth = Auth.Token(token)    # using an access token
  File "C:\Users\Серж\AppData\Local\Programs\Python\Python310\lib\site-packages\github\Auth.py", line 117, in __init__
    assert isinstance(token, str)
AssertionError

During handling of the above exception, another exception occurred:

Traceback (most recent call last):
  File "C:\Users\Серж\Desktop\TopLiga\TopLiga_webapp\TL_VS_solution\Content_prod\logics\modules\bug_mail.py", line 25, in bug_mail
    s.login(sender, password)
  File "C:\Users\Серж\AppData\Local\Programs\Python\Python310\lib\smtplib.py", line 739, in login
    (code, resp) = self.auth(
  File "C:\Users\Серж\AppData\Local\Programs\Python\Python310\lib\smtplib.py", line 652, in auth
    authobject(challenge).encode('ascii'), eol='')
AttributeError: 'NoneType' object has no attribute 'encode'

During handling of the above exception, another exception occurred:

Traceback (most recent call last):
  File "C:\Users\Серж\Desktop\TopLiga\TopLiga_webapp\TL_VS_solution\Content_prod\logics\modules\gh_push.py", line 42, in gh_push
    auth = Auth.Token(token)    # using an access token
  File "C:\Users\Серж\AppData\Local\Programs\Python\Python310\lib\site-packages\github\Auth.py", line 117, in __init__
    assert isinstance(token, str)
AssertionError

During handling of the above exception, another exception occurred:

Traceback (most recent call last):
  File "C:\Users\Серж\Desktop\TopLiga\TopLiga_webapp\TL_VS_solution\Content_prod\logics\modules\bug_mail.py", line 25, in bug_mail
    s.login(sender, password)
  File "C:\Users\Серж\AppData\Local\Programs\Python\Python310\lib\smtplib.py", line 739, in login
    (code, resp) = self.auth(
  File "C:\Users\Серж\AppData\Local\Programs\Python\Python310\lib\smtplib.py", line 652, in auth
    authobject(challenge).encode('ascii'), eol='')
AttributeError: 'NoneType' object has no attribute 'encode'

During handling of the above exception, another exception occurred:

Traceback (most recent call last):
  File "C:\Users\Серж\Desktop\TopLiga\TopLiga_webapp\TL_VS_solution\Content_prod\logics\modules\gh_push.py", line 42, in gh_push
    auth = Auth.Token(token)    # using an access token
  File "C:\Users\Серж\AppData\Local\Programs\Python\Python310\lib\site-packages\github\Auth.py", line 117, in __init__
    assert isinstance(token, str)
AssertionError

During handling of the above exception, another exception occurred:

Traceback (most recent call last):
  File "C:\Users\Серж\Desktop\TopLiga\TopLiga_webapp\TL_VS_solution\Content_prod\logics\modules\bug_mail.py", line 25, in bug_mail
    s.login(sender, password)
  File "C:\Users\Серж\AppData\Local\Programs\Python\Python310\lib\smtplib.py", line 739, in login
    (code, resp) = self.auth(
  File "C:\Users\Серж\AppData\Local\Programs\Python\Python310\lib\smtplib.py", line 652, in auth
    authobject(challenge).encode('ascii'), eol='')
AttributeError: 'NoneType' object has no attribute 'encode'

During handling of the above exception, another exception occurred:

Traceback (most recent call last):
  File "C:\Users\Серж\Desktop\TopLiga\TopLiga_webapp\TL_VS_solution\Content_prod\logics\modules\gh_push.py", line 42, in gh_push
    auth = Auth.Token(token)    # using an access token
  File "C:\Users\Серж\AppData\Local\Programs\Python\Python310\lib\site-packages\github\Auth.py", line 117, in __init__
    assert isinstance(token, str)
AssertionError

During handling of the above exception, another exception occurred:

Traceback (most recent call last):
  File "C:\Users\Серж\Desktop\TopLiga\TopLiga_webapp\TL_VS_solution\Content_prod\logics\modules\bug_mail.py", line 25, in bug_mail
    s.login(sender, password)
  File "C:\Users\Серж\AppData\Local\Programs\Python\Python310\lib\smtplib.py", line 739, in login
    (code, resp) = self.auth(
  File "C:\Users\Серж\AppData\Local\Programs\Python\Python310\lib\smtplib.py", line 652, in auth
    authobject(challenge).encode('ascii'), eol='')
AttributeError: 'NoneType' object has no attribute 'encode'

During handling of the above exception, another exception occurred:

Traceback (most recent call last):
  File "C:\Users\Серж\Desktop\TopLiga\TopLiga_webapp\TL_VS_solution\Content_prod\logics\modules\gh_push.py", line 42, in gh_push
    auth = Auth.Token(token)    # using an access token
  File "C:\Users\Серж\AppData\Local\Programs\Python\Python310\lib\site-packages\github\Auth.py", line 117, in __init__
    assert isinstance(token, str)
AssertionError

During handling of the above exception, another exception occurred:

Traceback (most recent call last):
  File "C:\Users\Серж\Desktop\TopLiga\TopLiga_webapp\TL_VS_solution\Content_prod\logics\modules\bug_mail.py", line 25, in bug_mail
    s.login(sender, password)
  File "C:\Users\Серж\AppData\Local\Programs\Python\Python310\lib\smtplib.py", line 739, in login
    (code, resp) = self.auth(
  File "C:\Users\Серж\AppData\Local\Programs\Python\Python310\lib\smtplib.py", line 652, in auth
    authobject(challenge).encode('ascii'), eol='')
AttributeError: 'NoneType' object has no attribute 'encode'

During handling of the above exception, another exception occurred:

Traceback (most recent call last):
  File "C:\Users\Серж\Desktop\TopLiga\TopLiga_webapp\TL_VS_solution\Content_prod\logics\modules\gh_push.py", line 42, in gh_push
    auth = Auth.Token(token)    # using an access token
  File "C:\Users\Серж\AppData\Local\Programs\Python\Python310\lib\site-packages\github\Auth.py", line 117, in __init__
    assert isinstance(token, str)
AssertionError

During handling of the above exception, another exception occurred:

Traceback (most recent call last):
  File "C:\Users\Серж\Desktop\TopLiga\TopLiga_webapp\TL_VS_solution\Content_prod\logics\modules\bug_mail.py", line 25, in bug_mail
    s.login(sender, password)
  File "C:\Users\Серж\AppData\Local\Programs\Python\Python310\lib\smtplib.py", line 739, in login
    (code, resp) = self.auth(
  File "C:\Users\Серж\AppData\Local\Programs\Python\Python310\lib\smtplib.py", line 652, in auth
    authobject(challenge).encode('ascii'), eol='')
AttributeError: 'NoneType' object has no attribute 'encode'

During handling of the above exception, another exception occurred:

Traceback (most recent call last):
  File "C:\Users\Серж\Desktop\TopLiga\TopLiga_webapp\TL_VS_solution\Content_prod\logics\modules\gh_push.py", line 42, in gh_push
    auth = Auth.Token(token)    # using an access token
  File "C:\Users\Серж\AppData\Local\Programs\Python\Python310\lib\site-packages\github\Auth.py", line 117, in __init__
    assert isinstance(token, str)
AssertionError

During handling of the above exception, another exception occurred:

Traceback (most recent call last):
  File "C:\Users\Серж\Desktop\TopLiga\TopLiga_webapp\TL_VS_solution\Content_prod\logics\modules\bug_mail.py", line 25, in bug_mail
    s.login(sender, password)
  File "C:\Users\Серж\AppData\Local\Programs\Python\Python310\lib\smtplib.py", line 739, in login
    (code, resp) = self.auth(
  File "C:\Users\Серж\AppData\Local\Programs\Python\Python310\lib\smtplib.py", line 652, in auth
    authobject(challenge).encode('ascii'), eol='')
AttributeError: 'NoneType' object has no attribute 'encode'

During handling of the above exception, another exception occurred:

Traceback (most recent call last):
  File "C:\Users\Серж\Desktop\TopLiga\TopLiga_webapp\TL_VS_solution\Content_prod\logics\modules\gh_push.py", line 42, in gh_push
    auth = Auth.Token(token)    # using an access token
  File "C:\Users\Серж\AppData\Local\Programs\Python\Python310\lib\site-packages\github\Auth.py", line 117, in __init__
    assert isinstance(token, str)
AssertionError

During handling of the above exception, another exception occurred:

Traceback (most recent call last):
  File "C:\Users\Серж\Desktop\TopLiga\TopLiga_webapp\TL_VS_solution\Content_prod\logics\modules\bug_mail.py", line 25, in bug_mail
    s.login(sender, password)
  File "C:\Users\Серж\AppData\Local\Programs\Python\Python310\lib\smtplib.py", line 739, in login
    (code, resp) = self.auth(
  File "C:\Users\Серж\AppData\Local\Programs\Python\Python310\lib\smtplib.py", line 652, in auth
    authobject(challenge).encode('ascii'), eol='')
AttributeError: 'NoneType' object has no attribute 'encode'

During handling of the above exception, another exception occurred:

Traceback (most recent call last):
  File "C:\Users\Серж\Desktop\TopLiga\TopLiga_webapp\TL_VS_solution\Content_prod\logics\modules\gh_push.py", line 42, in gh_push
    auth = Auth.Token(token)    # using an access token
  File "C:\Users\Серж\AppData\Local\Programs\Python\Python310\lib\site-packages\github\Auth.py", line 117, in __init__
    assert isinstance(token, str)
AssertionError

During handling of the above exception, another exception occurred:

Traceback (most recent call last):
  File "C:\Users\Серж\Desktop\TopLiga\TopLiga_webapp\TL_VS_solution\Content_prod\logics\modules\bug_mail.py", line 25, in bug_mail
    s.login(sender, password)
  File "C:\Users\Серж\AppData\Local\Programs\Python\Python310\lib\smtplib.py", line 739, in login
    (code, resp) = self.auth(
  File "C:\Users\Серж\AppData\Local\Programs\Python\Python310\lib\smtplib.py", line 652, in auth
    authobject(challenge).encode('ascii'), eol='')
AttributeError: 'NoneType' object has no attribute 'encode'

During handling of the above exception, another exception occurred:

Traceback (most recent call last):
  File "C:\Users\Серж\Desktop\TopLiga\TopLiga_webapp\TL_VS_solution\Content_prod\logics\modules\gh_push.py", line 42, in gh_push
    auth = Auth.Token(token)    # using an access token
  File "C:\Users\Серж\AppData\Local\Programs\Python\Python310\lib\site-packages\github\Auth.py", line 117, in __init__
    assert isinstance(token, str)
AssertionError

During handling of the above exception, another exception occurred:

Traceback (most recent call last):
  File "C:\Users\Серж\Desktop\TopLiga\TopLiga_webapp\TL_VS_solution\Content_prod\logics\modules\bug_mail.py", line 25, in bug_mail
    s.login(sender, password)
  File "C:\Users\Серж\AppData\Local\Programs\Python\Python310\lib\smtplib.py", line 739, in login
    (code, resp) = self.auth(
  File "C:\Users\Серж\AppData\Local\Programs\Python\Python310\lib\smtplib.py", line 652, in auth
    authobject(challenge).encode('ascii'), eol='')
AttributeError: 'NoneType' object has no attribute 'encode'

During handling of the above exception, another exception occurred:

Traceback (most recent call last):
  File "C:\Users\Серж\Desktop\TopLiga\TopLiga_webapp\TL_VS_solution\Content_prod\logics\modules\gh_push.py", line 42, in gh_push
    auth = Auth.Token(token)    # using an access token
  File "C:\Users\Серж\AppData\Local\Programs\Python\Python310\lib\site-packages\github\Auth.py", line 117, in __init__
    assert isinstance(token, str)
AssertionError

During handling of the above exception, another exception occurred:

Traceback (most recent call last):
  File "C:\Users\Серж\Desktop\TopLiga\TopLiga_webapp\TL_VS_solution\Content_prod\logics\modules\bug_mail.py", line 25, in bug_mail
    s.login(sender, password)
  File "C:\Users\Серж\AppData\Local\Programs\Python\Python310\lib\smtplib.py", line 739, in login
    (code, resp) = self.auth(
  File "C:\Users\Серж\AppData\Local\Programs\Python\Python310\lib\smtplib.py", line 652, in auth
    authobject(challenge).encode('ascii'), eol='')
AttributeError: 'NoneType' object has no attribute 'encode'

During handling of the above exception, another exception occurred:

Traceback (most recent call last):
  File "C:\Users\Серж\Desktop\TopLiga\TopLiga_webapp\TL_VS_solution\Content_prod\logics\modules\gh_push.py", line 42, in gh_push
    auth = Auth.Token(token)    # using an access token
  File "C:\Users\Серж\AppData\Local\Programs\Python\Python310\lib\site-packages\github\Auth.py", line 117, in __init__
    assert isinstance(token, str)
AssertionError

During handling of the above exception, another exception occurred:

Traceback (most recent call last):
  File "C:\Users\Серж\Desktop\TopLiga\TopLiga_webapp\TL_VS_solution\Content_prod\logics\modules\bug_mail.py", line 25, in bug_mail
    s.login(sender, password)
  File "C:\Users\Серж\AppData\Local\Programs\Python\Python310\lib\smtplib.py", line 739, in login
    (code, resp) = self.auth(
  File "C:\Users\Серж\AppData\Local\Programs\Python\Python310\lib\smtplib.py", line 652, in auth
    authobject(challenge).encode('ascii'), eol='')
AttributeError: 'NoneType' object has no attribute 'encode'

During handling of the above exception, another exception occurred:

Traceback (most recent call last):
  File "C:\Users\Серж\Desktop\TopLiga\TopLiga_webapp\TL_VS_solution\Content_prod\logics\modules\gh_push.py", line 42, in gh_push
    auth = Auth.Token(token)    # using an access token
  File "C:\Users\Серж\AppData\Local\Programs\Python\Python310\lib\site-packages\github\Auth.py", line 117, in __init__
    assert isinstance(token, str)
AssertionError

During handling of the above exception, another exception occurred:

Traceback (most recent call last):
  File "C:\Users\Серж\Desktop\TopLiga\TopLiga_webapp\TL_VS_solution\Content_prod\logics\modules\bug_mail.py", line 25, in bug_mail
    s.login(sender, password)
  File "C:\Users\Серж\AppData\Local\Programs\Python\Python310\lib\smtplib.py", line 739, in login
    (code, resp) = self.auth(
  File "C:\Users\Серж\AppData\Local\Programs\Python\Python310\lib\smtplib.py", line 652, in auth
    authobject(challenge).encode('ascii'), eol='')
AttributeError: 'NoneType' object has no attribute 'encode'

During handling of the above exception, another exception occurred:

Traceback (most recent call last):
  File "C:\Users\Серж\Desktop\TopLiga\TopLiga_webapp\TL_VS_solution\Content_prod\logics\modules\gh_push.py", line 42, in gh_push
    auth = Auth.Token(token)    # using an access token
  File "C:\Users\Серж\AppData\Local\Programs\Python\Python310\lib\site-packages\github\Auth.py", line 117, in __init__
    assert isinstance(token, str)
AssertionError

During handling of the above exception, another exception occurred:

Traceback (most recent call last):
  File "C:\Users\Серж\Desktop\TopLiga\TopLiga_webapp\TL_VS_solution\Content_prod\logics\modules\bug_mail.py", line 25, in bug_mail
    s.login(sender, password)
  File "C:\Users\Серж\AppData\Local\Programs\Python\Python310\lib\smtplib.py", line 739, in login
    (code, resp) = self.auth(
  File "C:\Users\Серж\AppData\Local\Programs\Python\Python310\lib\smtplib.py", line 652, in auth
    authobject(challenge).encode('ascii'), eol='')
AttributeError: 'NoneType' object has no attribute 'encode'

During handling of the above exception, another exception occurred:

Traceback (most recent call last):
  File "C:\Users\Серж\Desktop\TopLiga\TopLiga_webapp\TL_VS_solution\Content_prod\logics\modules\gh_push.py", line 42, in gh_push
    auth = Auth.Token(token)    # using an access token
  File "C:\Users\Серж\AppData\Local\Programs\Python\Python310\lib\site-packages\github\Auth.py", line 117, in __init__
    assert isinstance(token, str)
AssertionError

During handling of the above exception, another exception occurred:

Traceback (most recent call last):
  File "C:\Users\Серж\Desktop\TopLiga\TopLiga_webapp\TL_VS_solution\Content_prod\logics\modules\bug_mail.py", line 25, in bug_mail
    s.login(sender, password)
  File "C:\Users\Серж\AppData\Local\Programs\Python\Python310\lib\smtplib.py", line 739, in login
    (code, resp) = self.auth(
  File "C:\Users\Серж\AppData\Local\Programs\Python\Python310\lib\smtplib.py", line 652, in auth
    authobject(challenge).encode('ascii'), eol='')
AttributeError: 'NoneType' object has no attribute 'encode'

During handling of the above exception, another exception occurred:

Traceback (most recent call last):
  File "C:\Users\Серж\Desktop\TopLiga\TopLiga_webapp\TL_VS_solution\Content_prod\logics\modules\gh_push.py", line 42, in gh_push
    auth = Auth.Token(token)    # using an access token
  File "C:\Users\Серж\AppData\Local\Programs\Python\Python310\lib\site-packages\github\Auth.py", line 117, in __init__
    assert isinstance(token, str)
AssertionError

During handling of the above exception, another exception occurred:

Traceback (most recent call last):
  File "C:\Users\Серж\Desktop\TopLiga\TopLiga_webapp\TL_VS_solution\Content_prod\logics\modules\bug_mail.py", line 25, in bug_mail
    s.login(sender, password)
  File "C:\Users\Серж\AppData\Local\Programs\Python\Python310\lib\smtplib.py", line 739, in login
    (code, resp) = self.auth(
  File "C:\Users\Серж\AppData\Local\Programs\Python\Python310\lib\smtplib.py", line 652, in auth
    authobject(challenge).encode('ascii'), eol='')
AttributeError: 'NoneType' object has no attribute 'encode'

During handling of the above exception, another exception occurred:

Traceback (most recent call last):
  File "C:\Users\Серж\Desktop\TopLiga\TopLiga_webapp\TL_VS_solution\Content_prod\logics\modules\gh_push.py", line 42, in gh_push
    auth = Auth.Token(token)    # using an access token
  File "C:\Users\Серж\AppData\Local\Programs\Python\Python310\lib\site-packages\github\Auth.py", line 117, in __init__
    assert isinstance(token, str)
AssertionError

During handling of the above exception, another exception occurred:

Traceback (most recent call last):
  File "C:\Users\Серж\Desktop\TopLiga\TopLiga_webapp\TL_VS_solution\Content_prod\logics\modules\bug_mail.py", line 25, in bug_mail
    s.login(sender, password)
  File "C:\Users\Серж\AppData\Local\Programs\Python\Python310\lib\smtplib.py", line 739, in login
    (code, resp) = self.auth(
  File "C:\Users\Серж\AppData\Local\Programs\Python\Python310\lib\smtplib.py", line 652, in auth
    authobject(challenge).encode('ascii'), eol='')
AttributeError: 'NoneType' object has no attribute 'encode'

During handling of the above exception, another exception occurred:

Traceback (most recent call last):
  File "C:\Users\Серж\Desktop\TopLiga\TopLiga_webapp\TL_VS_solution\Content_prod\logics\modules\gh_push.py", line 42, in gh_push
    auth = Auth.Token(token)    # using an access token
  File "C:\Users\Серж\AppData\Local\Programs\Python\Python310\lib\site-packages\github\Auth.py", line 117, in __init__
    assert isinstance(token, str)
AssertionError

During handling of the above exception, another exception occurred:

Traceback (most recent call last):
  File "C:\Users\Серж\Desktop\TopLiga\TopLiga_webapp\TL_VS_solution\Content_prod\logics\modules\bug_mail.py", line 25, in bug_mail
    s.login(sender, password)
  File "C:\Users\Серж\AppData\Local\Programs\Python\Python310\lib\smtplib.py", line 739, in login
    (code, resp) = self.auth(
  File "C:\Users\Серж\AppData\Local\Programs\Python\Python310\lib\smtplib.py", line 652, in auth
    authobject(challenge).encode('ascii'), eol='')
AttributeError: 'NoneType' object has no attribute 'encode'

During handling of the above exception, another exception occurred:

Traceback (most recent call last):
  File "C:\Users\Серж\Desktop\TopLiga\TopLiga_webapp\TL_VS_solution\Content_prod\logics\modules\gh_push.py", line 42, in gh_push
    auth = Auth.Token(token)    # using an access token
  File "C:\Users\Серж\AppData\Local\Programs\Python\Python310\lib\site-packages\github\Auth.py", line 117, in __init__
    assert isinstance(token, str)
AssertionError

During handling of the above exception, another exception occurred:

Traceback (most recent call last):
  File "C:\Users\Серж\Desktop\TopLiga\TopLiga_webapp\TL_VS_solution\Content_prod\logics\modules\bug_mail.py", line 25, in bug_mail
    s.login(sender, password)
  File "C:\Users\Серж\AppData\Local\Programs\Python\Python310\lib\smtplib.py", line 739, in login
    (code, resp) = self.auth(
  File "C:\Users\Серж\AppData\Local\Programs\Python\Python310\lib\smtplib.py", line 652, in auth
    authobject(challenge).encode('ascii'), eol='')
AttributeError: 'NoneType' object has no attribute 'encode'

During handling of the above exception, another exception occurred:

Traceback (most recent call last):
  File "C:\Users\Серж\Desktop\TopLiga\TopLiga_webapp\TL_VS_solution\Content_prod\logics\modules\gh_push.py", line 42, in gh_push
    auth = Auth.Token(token)    # using an access token
  File "C:\Users\Серж\AppData\Local\Programs\Python\Python310\lib\site-packages\github\Auth.py", line 117, in __init__
    assert isinstance(token, str)
AssertionError

During handling of the above exception, another exception occurred:

Traceback (most recent call last):
  File "C:\Users\Серж\Desktop\TopLiga\TopLiga_webapp\TL_VS_solution\Content_prod\logics\modules\bug_mail.py", line 25, in bug_mail
    s.login(sender, password)
  File "C:\Users\Серж\AppData\Local\Programs\Python\Python310\lib\smtplib.py", line 739, in login
    (code, resp) = self.auth(
  File "C:\Users\Серж\AppData\Local\Programs\Python\Python310\lib\smtplib.py", line 652, in auth
    authobject(challenge).encode('ascii'), eol='')
AttributeError: 'NoneType' object has no attribute 'encode'

During handling of the above exception, another exception occurred:

Traceback (most recent call last):
  File "C:\Users\Серж\Desktop\TopLiga\TopLiga_webapp\TL_VS_solution\Content_prod\logics\modules\gh_push.py", line 42, in gh_push
    auth = Auth.Token(token)    # using an access token
  File "C:\Users\Серж\AppData\Local\Programs\Python\Python310\lib\site-packages\github\Auth.py", line 117, in __init__
    assert isinstance(token, str)
AssertionError

During handling of the above exception, another exception occurred:

Traceback (most recent call last):
  File "C:\Users\Серж\Desktop\TopLiga\TopLiga_webapp\TL_VS_solution\Content_prod\logics\modules\bug_mail.py", line 25, in bug_mail
    s.login(sender, password)
  File "C:\Users\Серж\AppData\Local\Programs\Python\Python310\lib\smtplib.py", line 739, in login
    (code, resp) = self.auth(
  File "C:\Users\Серж\AppData\Local\Programs\Python\Python310\lib\smtplib.py", line 652, in auth
    authobject(challenge).encode('ascii'), eol='')
AttributeError: 'NoneType' object has no attribute 'encode'

During handling of the above exception, another exception occurred:

Traceback (most recent call last):
  File "C:\Users\Серж\Desktop\TopLiga\TopLiga_webapp\TL_VS_solution\Content_prod\logics\modules\gh_push.py", line 42, in gh_push
    auth = Auth.Token(token)    # using an access token
  File "C:\Users\Серж\AppData\Local\Programs\Python\Python310\lib\site-packages\github\Auth.py", line 117, in __init__
    assert isinstance(token, str)
AssertionError

During handling of the above exception, another exception occurred:

Traceback (most recent call last):
  File "C:\Users\Серж\Desktop\TopLiga\TopLiga_webapp\TL_VS_solution\Content_prod\logics\modules\bug_mail.py", line 25, in bug_mail
    s.login(sender, password)
  File "C:\Users\Серж\AppData\Local\Programs\Python\Python310\lib\smtplib.py", line 739, in login
    (code, resp) = self.auth(
  File "C:\Users\Серж\AppData\Local\Programs\Python\Python310\lib\smtplib.py", line 652, in auth
    authobject(challenge).encode('ascii'), eol='')
AttributeError: 'NoneType' object has no attribute 'encode'

During handling of the above exception, another exception occurred:

Traceback (most recent call last):
  File "C:\Users\Серж\Desktop\TopLiga\TopLiga_webapp\TL_VS_solution\Content_prod\logics\modules\gh_push.py", line 42, in gh_push
    auth = Auth.Token(token)    # using an access token
  File "C:\Users\Серж\AppData\Local\Programs\Python\Python310\lib\site-packages\github\Auth.py", line 117, in __init__
    assert isinstance(token, str)
AssertionError

During handling of the above exception, another exception occurred:

Traceback (most recent call last):
  File "C:\Users\Серж\Desktop\TopLiga\TopLiga_webapp\TL_VS_solution\Content_prod\logics\modules\bug_mail.py", line 25, in bug_mail
    s.login(sender, password)
  File "C:\Users\Серж\AppData\Local\Programs\Python\Python310\lib\smtplib.py", line 739, in login
    (code, resp) = self.auth(
  File "C:\Users\Серж\AppData\Local\Programs\Python\Python310\lib\smtplib.py", line 652, in auth
    authobject(challenge).encode('ascii'), eol='')
AttributeError: 'NoneType' object has no attribute 'encode'

During handling of the above exception, another exception occurred:

Traceback (most recent call last):
  File "C:\Users\Серж\Desktop\TopLiga\TopLiga_webapp\TL_VS_solution\Content_prod\logics\modules\gh_push.py", line 42, in gh_push
    auth = Auth.Token(token)    # using an access token
  File "C:\Users\Серж\AppData\Local\Programs\Python\Python310\lib\site-packages\github\Auth.py", line 117, in __init__
    assert isinstance(token, str)
AssertionError

During handling of the above exception, another exception occurred:

Traceback (most recent call last):
  File "C:\Users\Серж\Desktop\TopLiga\TopLiga_webapp\TL_VS_solution\Content_prod\logics\modules\bug_mail.py", line 25, in bug_mail
    s.login(sender, password)
  File "C:\Users\Серж\AppData\Local\Programs\Python\Python310\lib\smtplib.py", line 739, in login
    (code, resp) = self.auth(
  File "C:\Users\Серж\AppData\Local\Programs\Python\Python310\lib\smtplib.py", line 652, in auth
    authobject(challenge).encode('ascii'), eol='')
AttributeError: 'NoneType' object has no attribute 'encode'

During handling of the above exception, another exception occurred:

Traceback (most recent call last):
  File "C:\Users\Серж\Desktop\TopLiga\TopLiga_webapp\TL_VS_solution\Content_prod\logics\modules\gh_push.py", line 42, in gh_push
    auth = Auth.Token(token)    # using an access token
  File "C:\Users\Серж\AppData\Local\Programs\Python\Python310\lib\site-packages\github\Auth.py", line 117, in __init__
    assert isinstance(token, str)
AssertionError

During handling of the above exception, another exception occurred:

Traceback (most recent call last):
  File "C:\Users\Серж\Desktop\TopLiga\TopLiga_webapp\TL_VS_solution\Content_prod\logics\modules\bug_mail.py", line 25, in bug_mail
    s.login(sender, password)
  File "C:\Users\Серж\AppData\Local\Programs\Python\Python310\lib\smtplib.py", line 739, in login
    (code, resp) = self.auth(
  File "C:\Users\Серж\AppData\Local\Programs\Python\Python310\lib\smtplib.py", line 652, in auth
    authobject(challenge).encode('ascii'), eol='')
AttributeError: 'NoneType' object has no attribute 'encode'

During handling of the above exception, another exception occurred:

Traceback (most recent call last):
  File "C:\Users\Серж\Desktop\TopLiga\TopLiga_webapp\TL_VS_solution\Content_prod\logics\modules\gh_push.py", line 42, in gh_push
    auth = Auth.Token(token)    # using an access token
  File "C:\Users\Серж\AppData\Local\Programs\Python\Python310\lib\site-packages\github\Auth.py", line 117, in __init__
    assert isinstance(token, str)
AssertionError

During handling of the above exception, another exception occurred:

Traceback (most recent call last):
  File "C:\Users\Серж\Desktop\TopLiga\TopLiga_webapp\TL_VS_solution\Content_prod\logics\modules\bug_mail.py", line 25, in bug_mail
    s.login(sender, password)
  File "C:\Users\Серж\AppData\Local\Programs\Python\Python310\lib\smtplib.py", line 739, in login
    (code, resp) = self.auth(
  File "C:\Users\Серж\AppData\Local\Programs\Python\Python310\lib\smtplib.py", line 652, in auth
    authobject(challenge).encode('ascii'), eol='')
AttributeError: 'NoneType' object has no attribute 'encode'

During handling of the above exception, another exception occurred:

Traceback (most recent call last):
  File "C:\Users\Серж\Desktop\TopLiga\TopLiga_webapp\TL_VS_solution\Content_prod\logics\modules\gh_push.py", line 42, in gh_push
    auth = Auth.Token(token)    # using an access token
  File "C:\Users\Серж\AppData\Local\Programs\Python\Python310\lib\site-packages\github\Auth.py", line 117, in __init__
    assert isinstance(token, str)
AssertionError

During handling of the above exception, another exception occurred:

Traceback (most recent call last):
  File "C:\Users\Серж\Desktop\TopLiga\TopLiga_webapp\TL_VS_solution\Content_prod\logics\modules\bug_mail.py", line 25, in bug_mail
    s.login(sender, password)
  File "C:\Users\Серж\AppData\Local\Programs\Python\Python310\lib\smtplib.py", line 739, in login
    (code, resp) = self.auth(
  File "C:\Users\Серж\AppData\Local\Programs\Python\Python310\lib\smtplib.py", line 652, in auth
    authobject(challenge).encode('ascii'), eol='')
AttributeError: 'NoneType' object has no attribute 'encode'

During handling of the above exception, another exception occurred:

Traceback (most recent call last):
  File "C:\Users\Серж\Desktop\TopLiga\TopLiga_webapp\TL_VS_solution\Content_prod\logics\modules\gh_push.py", line 42, in gh_push
    auth = Auth.Token(token)    # using an access token
  File "C:\Users\Серж\AppData\Local\Programs\Python\Python310\lib\site-packages\github\Auth.py", line 117, in __init__
    assert isinstance(token, str)
AssertionError

During handling of the above exception, another exception occurred:

Traceback (most recent call last):
  File "C:\Users\Серж\Desktop\TopLiga\TopLiga_webapp\TL_VS_solution\Content_prod\logics\modules\bug_mail.py", line 25, in bug_mail
    s.login(sender, password)
  File "C:\Users\Серж\AppData\Local\Programs\Python\Python310\lib\smtplib.py", line 739, in login
    (code, resp) = self.auth(
  File "C:\Users\Серж\AppData\Local\Programs\Python\Python310\lib\smtplib.py", line 652, in auth
    authobject(challenge).encode('ascii'), eol='')
AttributeError: 'NoneType' object has no attribute 'encode'

During handling of the above exception, another exception occurred:

Traceback (most recent call last):
  File "C:\Users\Серж\Desktop\TopLiga\TopLiga_webapp\TL_VS_solution\Content_prod\logics\modules\gh_push.py", line 42, in gh_push
    auth = Auth.Token(token)    # using an access token
  File "C:\Users\Серж\AppData\Local\Programs\Python\Python310\lib\site-packages\github\Auth.py", line 117, in __init__
    assert isinstance(token, str)
AssertionError

During handling of the above exception, another exception occurred:

Traceback (most recent call last):
  File "C:\Users\Серж\Desktop\TopLiga\TopLiga_webapp\TL_VS_solution\Content_prod\logics\modules\bug_mail.py", line 25, in bug_mail
    s.login(sender, password)
  File "C:\Users\Серж\AppData\Local\Programs\Python\Python310\lib\smtplib.py", line 739, in login
    (code, resp) = self.auth(
  File "C:\Users\Серж\AppData\Local\Programs\Python\Python310\lib\smtplib.py", line 652, in auth
    authobject(challenge).encode('ascii'), eol='')
AttributeError: 'NoneType' object has no attribute 'encode'

During handling of the above exception, another exception occurred:

Traceback (most recent call last):
  File "C:\Users\Серж\Desktop\TopLiga\TopLiga_webapp\TL_VS_solution\Content_prod\logics\modules\gh_push.py", line 42, in gh_push
    auth = Auth.Token(token)    # using an access token
  File "C:\Users\Серж\AppData\Local\Programs\Python\Python310\lib\site-packages\github\Auth.py", line 117, in __init__
    assert isinstance(token, str)
AssertionError

During handling of the above exception, another exception occurred:

Traceback (most recent call last):
  File "C:\Users\Серж\Desktop\TopLiga\TopLiga_webapp\TL_VS_solution\Content_prod\logics\modules\bug_mail.py", line 25, in bug_mail
    s.login(sender, password)
  File "C:\Users\Серж\AppData\Local\Programs\Python\Python310\lib\smtplib.py", line 739, in login
    (code, resp) = self.auth(
  File "C:\Users\Серж\AppData\Local\Programs\Python\Python310\lib\smtplib.py", line 652, in auth
    authobject(challenge).encode('ascii'), eol='')
AttributeError: 'NoneType' object has no attribute 'encode'

During handling of the above exception, another exception occurred:

Traceback (most recent call last):
  File "C:\Users\Серж\Desktop\TopLiga\TopLiga_webapp\TL_VS_solution\Content_prod\logics\modules\gh_push.py", line 42, in gh_push
    auth = Auth.Token(token)    # using an access token
  File "C:\Users\Серж\AppData\Local\Programs\Python\Python310\lib\site-packages\github\Auth.py", line 117, in __init__
    assert isinstance(token, str)
AssertionError

During handling of the above exception, another exception occurred:

Traceback (most recent call last):
  File "C:\Users\Серж\Desktop\TopLiga\TopLiga_webapp\TL_VS_solution\Content_prod\logics\modules\bug_mail.py", line 25, in bug_mail
    s.login(sender, password)
  File "C:\Users\Серж\AppData\Local\Programs\Python\Python310\lib\smtplib.py", line 739, in login
    (code, resp) = self.auth(
  File "C:\Users\Серж\AppData\Local\Programs\Python\Python310\lib\smtplib.py", line 652, in auth
    authobject(challenge).encode('ascii'), eol='')
AttributeError: 'NoneType' object has no attribute 'encode'

During handling of the above exception, another exception occurred:

Traceback (most recent call last):
  File "C:\Users\Серж\Desktop\TopLiga\TopLiga_webapp\TL_VS_solution\Content_prod\logics\modules\gh_push.py", line 42, in gh_push
    auth = Auth.Token(token)    # using an access token
  File "C:\Users\Серж\AppData\Local\Programs\Python\Python310\lib\site-packages\github\Auth.py", line 117, in __init__
    assert isinstance(token, str)
AssertionError

During handling of the above exception, another exception occurred:

Traceback (most recent call last):
  File "C:\Users\Серж\Desktop\TopLiga\TopLiga_webapp\TL_VS_solution\Content_prod\logics\modules\bug_mail.py", line 25, in bug_mail
    s.login(sender, password)
  File "C:\Users\Серж\AppData\Local\Programs\Python\Python310\lib\smtplib.py", line 739, in login
    (code, resp) = self.auth(
  File "C:\Users\Серж\AppData\Local\Programs\Python\Python310\lib\smtplib.py", line 652, in auth
    authobject(challenge).encode('ascii'), eol='')
AttributeError: 'NoneType' object has no attribute 'encode'

During handling of the above exception, another exception occurred:

Traceback (most recent call last):
  File "C:\Users\Серж\Desktop\TopLiga\TopLiga_webapp\TL_VS_solution\Content_prod\logics\modules\gh_push.py", line 42, in gh_push
    auth = Auth.Token(token)    # using an access token
  File "C:\Users\Серж\AppData\Local\Programs\Python\Python310\lib\site-packages\github\Auth.py", line 117, in __init__
    assert isinstance(token, str)
AssertionError

During handling of the above exception, another exception occurred:

Traceback (most recent call last):
  File "C:\Users\Серж\Desktop\TopLiga\TopLiga_webapp\TL_VS_solution\Content_prod\logics\modules\bug_mail.py", line 25, in bug_mail
    s.login(sender, password)
  File "C:\Users\Серж\AppData\Local\Programs\Python\Python310\lib\smtplib.py", line 739, in login
    (code, resp) = self.auth(
  File "C:\Users\Серж\AppData\Local\Programs\Python\Python310\lib\smtplib.py", line 652, in auth
    authobject(challenge).encode('ascii'), eol='')
AttributeError: 'NoneType' object has no attribute 'encode'

During handling of the above exception, another exception occurred:

Traceback (most recent call last):
  File "C:\Users\Серж\Desktop\TopLiga\TopLiga_webapp\TL_VS_solution\Content_prod\logics\modules\gh_push.py", line 42, in gh_push
    auth = Auth.Token(token)    # using an access token
  File "C:\Users\Серж\AppData\Local\Programs\Python\Python310\lib\site-packages\github\Auth.py", line 117, in __init__
    assert isinstance(token, str)
AssertionError

During handling of the above exception, another exception occurred:

Traceback (most recent call last):
  File "C:\Users\Серж\Desktop\TopLiga\TopLiga_webapp\TL_VS_solution\Content_prod\logics\modules\bug_mail.py", line 25, in bug_mail
    s.login(sender, password)
  File "C:\Users\Серж\AppData\Local\Programs\Python\Python310\lib\smtplib.py", line 739, in login
    (code, resp) = self.auth(
  File "C:\Users\Серж\AppData\Local\Programs\Python\Python310\lib\smtplib.py", line 652, in auth
    authobject(challenge).encode('ascii'), eol='')
AttributeError: 'NoneType' object has no attribute 'encode'

During handling of the above exception, another exception occurred:

Traceback (most recent call last):
  File "C:\Users\Серж\Desktop\TopLiga\TopLiga_webapp\TL_VS_solution\Content_prod\logics\modules\gh_push.py", line 42, in gh_push
    auth = Auth.Token(token)    # using an access token
  File "C:\Users\Серж\AppData\Local\Programs\Python\Python310\lib\site-packages\github\Auth.py", line 117, in __init__
    assert isinstance(token, str)
AssertionError

During handling of the above exception, another exception occurred:

Traceback (most recent call last):
  File "C:\Users\Серж\Desktop\TopLiga\TopLiga_webapp\TL_VS_solution\Content_prod\logics\modules\bug_mail.py", line 25, in bug_mail
    s.login(sender, password)
  File "C:\Users\Серж\AppData\Local\Programs\Python\Python310\lib\smtplib.py", line 739, in login
    (code, resp) = self.auth(
  File "C:\Users\Серж\AppData\Local\Programs\Python\Python310\lib\smtplib.py", line 652, in auth
    authobject(challenge).encode('ascii'), eol='')
AttributeError: 'NoneType' object has no attribute 'encode'

During handling of the above exception, another exception occurred:

Traceback (most recent call last):
  File "C:\Users\Серж\Desktop\TopLiga\TopLiga_webapp\TL_VS_solution\Content_prod\logics\modules\gh_push.py", line 42, in gh_push
    auth = Auth.Token(token)    # using an access token
  File "C:\Users\Серж\AppData\Local\Programs\Python\Python310\lib\site-packages\github\Auth.py", line 117, in __init__
    assert isinstance(token, str)
AssertionError

During handling of the above exception, another exception occurred:

Traceback (most recent call last):
  File "C:\Users\Серж\Desktop\TopLiga\TopLiga_webapp\TL_VS_solution\Content_prod\logics\modules\bug_mail.py", line 25, in bug_mail
    s.login(sender, password)
  File "C:\Users\Серж\AppData\Local\Programs\Python\Python310\lib\smtplib.py", line 739, in login
    (code, resp) = self.auth(
  File "C:\Users\Серж\AppData\Local\Programs\Python\Python310\lib\smtplib.py", line 652, in auth
    authobject(challenge).encode('ascii'), eol='')
AttributeError: 'NoneType' object has no attribute 'encode'

During handling of the above exception, another exception occurred:

Traceback (most recent call last):
  File "C:\Users\Серж\Desktop\TopLiga\TopLiga_webapp\TL_VS_solution\Content_prod\logics\modules\gh_push.py", line 42, in gh_push
    auth = Auth.Token(token)    # using an access token
  File "C:\Users\Серж\AppData\Local\Programs\Python\Python310\lib\site-packages\github\Auth.py", line 117, in __init__
    assert isinstance(token, str)
AssertionError

During handling of the above exception, another exception occurred:

Traceback (most recent call last):
  File "C:\Users\Серж\Desktop\TopLiga\TopLiga_webapp\TL_VS_solution\Content_prod\logics\modules\bug_mail.py", line 25, in bug_mail
    s.login(sender, password)
  File "C:\Users\Серж\AppData\Local\Programs\Python\Python310\lib\smtplib.py", line 739, in login
    (code, resp) = self.auth(
  File "C:\Users\Серж\AppData\Local\Programs\Python\Python310\lib\smtplib.py", line 652, in auth
    authobject(challenge).encode('ascii'), eol='')
AttributeError: 'NoneType' object has no attribute 'encode'

During handling of the above exception, another exception occurred:

Traceback (most recent call last):
  File "C:\Users\Серж\Desktop\TopLiga\TopLiga_webapp\TL_VS_solution\Content_prod\logics\modules\gh_push.py", line 42, in gh_push
    auth = Auth.Token(token)    # using an access token
  File "C:\Users\Серж\AppData\Local\Programs\Python\Python310\lib\site-packages\github\Auth.py", line 117, in __init__
    assert isinstance(token, str)
AssertionError

During handling of the above exception, another exception occurred:

Traceback (most recent call last):
  File "C:\Users\Серж\Desktop\TopLiga\TopLiga_webapp\TL_VS_solution\Content_prod\logics\modules\bug_mail.py", line 25, in bug_mail
    s.login(sender, password)
  File "C:\Users\Серж\AppData\Local\Programs\Python\Python310\lib\smtplib.py", line 739, in login
    (code, resp) = self.auth(
  File "C:\Users\Серж\AppData\Local\Programs\Python\Python310\lib\smtplib.py", line 652, in auth
    authobject(challenge).encode('ascii'), eol='')
AttributeError: 'NoneType' object has no attribute 'encode'

During handling of the above exception, another exception occurred:

Traceback (most recent call last):
  File "C:\Users\Серж\Desktop\TopLiga\TopLiga_webapp\TL_VS_solution\Content_prod\logics\modules\gh_push.py", line 42, in gh_push
    auth = Auth.Token(token)    # using an access token
  File "C:\Users\Серж\AppData\Local\Programs\Python\Python310\lib\site-packages\github\Auth.py", line 117, in __init__
    assert isinstance(token, str)
AssertionError

During handling of the above exception, another exception occurred:

Traceback (most recent call last):
  File "C:\Users\Серж\Desktop\TopLiga\TopLiga_webapp\TL_VS_solution\Content_prod\logics\modules\bug_mail.py", line 25, in bug_mail
    s.login(sender, password)
  File "C:\Users\Серж\AppData\Local\Programs\Python\Python310\lib\smtplib.py", line 739, in login
    (code, resp) = self.auth(
  File "C:\Users\Серж\AppData\Local\Programs\Python\Python310\lib\smtplib.py", line 652, in auth
    authobject(challenge).encode('ascii'), eol='')
AttributeError: 'NoneType' object has no attribute 'encode'

During handling of the above exception, another exception occurred:

Traceback (most recent call last):
  File "C:\Users\Серж\Desktop\TopLiga\TopLiga_webapp\TL_VS_solution\Content_prod\logics\modules\gh_push.py", line 42, in gh_push
    auth = Auth.Token(token)    # using an access token
  File "C:\Users\Серж\AppData\Local\Programs\Python\Python310\lib\site-packages\github\Auth.py", line 117, in __init__
    assert isinstance(token, str)
AssertionError

During handling of the above exception, another exception occurred:

Traceback (most recent call last):
  File "C:\Users\Серж\Desktop\TopLiga\TopLiga_webapp\TL_VS_solution\Content_prod\logics\modules\bug_mail.py", line 25, in bug_mail
    s.login(sender, password)
  File "C:\Users\Серж\AppData\Local\Programs\Python\Python310\lib\smtplib.py", line 739, in login
    (code, resp) = self.auth(
  File "C:\Users\Серж\AppData\Local\Programs\Python\Python310\lib\smtplib.py", line 652, in auth
    authobject(challenge).encode('ascii'), eol='')
AttributeError: 'NoneType' object has no attribute 'encode'

During handling of the above exception, another exception occurred:

Traceback (most recent call last):
  File "C:\Users\Серж\Desktop\TopLiga\TopLiga_webapp\TL_VS_solution\Content_prod\logics\modules\gh_push.py", line 42, in gh_push
    auth = Auth.Token(token)    # using an access token
  File "C:\Users\Серж\AppData\Local\Programs\Python\Python310\lib\site-packages\github\Auth.py", line 117, in __init__
    assert isinstance(token, str)
AssertionError

During handling of the above exception, another exception occurred:

Traceback (most recent call last):
  File "C:\Users\Серж\Desktop\TopLiga\TopLiga_webapp\TL_VS_solution\Content_prod\logics\modules\bug_mail.py", line 25, in bug_mail
    s.login(sender, password)
  File "C:\Users\Серж\AppData\Local\Programs\Python\Python310\lib\smtplib.py", line 739, in login
    (code, resp) = self.auth(
  File "C:\Users\Серж\AppData\Local\Programs\Python\Python310\lib\smtplib.py", line 652, in auth
    authobject(challenge).encode('ascii'), eol='')
AttributeError: 'NoneType' object has no attribute 'encode'

During handling of the above exception, another exception occurred:

Traceback (most recent call last):
  File "C:\Users\Серж\Desktop\TopLiga\TopLiga_webapp\TL_VS_solution\Content_prod\logics\modules\gh_push.py", line 42, in gh_push
    auth = Auth.Token(token)    # using an access token
  File "C:\Users\Серж\AppData\Local\Programs\Python\Python310\lib\site-packages\github\Auth.py", line 117, in __init__
    assert isinstance(token, str)
AssertionError

During handling of the above exception, another exception occurred:

Traceback (most recent call last):
  File "C:\Users\Серж\Desktop\TopLiga\TopLiga_webapp\TL_VS_solution\Content_prod\logics\modules\bug_mail.py", line 25, in bug_mail
    s.login(sender, password)
  File "C:\Users\Серж\AppData\Local\Programs\Python\Python310\lib\smtplib.py", line 739, in login
    (code, resp) = self.auth(
  File "C:\Users\Серж\AppData\Local\Programs\Python\Python310\lib\smtplib.py", line 652, in auth
    authobject(challenge).encode('ascii'), eol='')
AttributeError: 'NoneType' object has no attribute 'encode'

During handling of the above exception, another exception occurred:

Traceback (most recent call last):
  File "C:\Users\Серж\Desktop\TopLiga\TopLiga_webapp\TL_VS_solution\Content_prod\logics\modules\gh_push.py", line 42, in gh_push
    auth = Auth.Token(token)    # using an access token
  File "C:\Users\Серж\AppData\Local\Programs\Python\Python310\lib\site-packages\github\Auth.py", line 117, in __init__
    assert isinstance(token, str)
AssertionError

During handling of the above exception, another exception occurred:

Traceback (most recent call last):
  File "C:\Users\Серж\Desktop\TopLiga\TopLiga_webapp\TL_VS_solution\Content_prod\logics\modules\bug_mail.py", line 25, in bug_mail
    s.login(sender, password)
  File "C:\Users\Серж\AppData\Local\Programs\Python\Python310\lib\smtplib.py", line 739, in login
    (code, resp) = self.auth(
  File "C:\Users\Серж\AppData\Local\Programs\Python\Python310\lib\smtplib.py", line 652, in auth
    authobject(challenge).encode('ascii'), eol='')
AttributeError: 'NoneType' object has no attribute 'encode'

During handling of the above exception, another exception occurred:

Traceback (most recent call last):
  File "C:\Users\Серж\Desktop\TopLiga\TopLiga_webapp\TL_VS_solution\Content_prod\logics\modules\gh_push.py", line 42, in gh_push
    auth = Auth.Token(token)    # using an access token
  File "C:\Users\Серж\AppData\Local\Programs\Python\Python310\lib\site-packages\github\Auth.py", line 117, in __init__
    assert isinstance(token, str)
AssertionError

During handling of the above exception, another exception occurred:

Traceback (most recent call last):
  File "C:\Users\Серж\Desktop\TopLiga\TopLiga_webapp\TL_VS_solution\Content_prod\logics\modules\bug_mail.py", line 25, in bug_mail
    s.login(sender, password)
  File "C:\Users\Серж\AppData\Local\Programs\Python\Python310\lib\smtplib.py", line 739, in login
    (code, resp) = self.auth(
  File "C:\Users\Серж\AppData\Local\Programs\Python\Python310\lib\smtplib.py", line 652, in auth
    authobject(challenge).encode('ascii'), eol='')
AttributeError: 'NoneType' object has no attribute 'encode'

During handling of the above exception, another exception occurred:

Traceback (most recent call last):
  File "C:\Users\Серж\Desktop\TopLiga\TopLiga_webapp\TL_VS_solution\Content_prod\logics\modules\gh_push.py", line 42, in gh_push
    auth = Auth.Token(token)    # using an access token
  File "C:\Users\Серж\AppData\Local\Programs\Python\Python310\lib\site-packages\github\Auth.py", line 117, in __init__
    assert isinstance(token, str)
AssertionError

During handling of the above exception, another exception occurred:

Traceback (most recent call last):
  File "C:\Users\Серж\Desktop\TopLiga\TopLiga_webapp\TL_VS_solution\Content_prod\logics\modules\bug_mail.py", line 25, in bug_mail
    s.login(sender, password)
  File "C:\Users\Серж\AppData\Local\Programs\Python\Python310\lib\smtplib.py", line 739, in login
    (code, resp) = self.auth(
  File "C:\Users\Серж\AppData\Local\Programs\Python\Python310\lib\smtplib.py", line 652, in auth
    authobject(challenge).encode('ascii'), eol='')
AttributeError: 'NoneType' object has no attribute 'encode'

During handling of the above exception, another exception occurred:

Traceback (most recent call last):
  File "C:\Users\Серж\Desktop\TopLiga\TopLiga_webapp\TL_VS_solution\Content_prod\logics\modules\gh_push.py", line 42, in gh_push
    auth = Auth.Token(token)    # using an access token
  File "C:\Users\Серж\AppData\Local\Programs\Python\Python310\lib\site-packages\github\Auth.py", line 117, in __init__
    assert isinstance(token, str)
AssertionError

During handling of the above exception, another exception occurred:

Traceback (most recent call last):
  File "C:\Users\Серж\Desktop\TopLiga\TopLiga_webapp\TL_VS_solution\Content_prod\logics\modules\bug_mail.py", line 25, in bug_mail
    s.login(sender, password)
  File "C:\Users\Серж\AppData\Local\Programs\Python\Python310\lib\smtplib.py", line 739, in login
    (code, resp) = self.auth(
  File "C:\Users\Серж\AppData\Local\Programs\Python\Python310\lib\smtplib.py", line 652, in auth
    authobject(challenge).encode('ascii'), eol='')
AttributeError: 'NoneType' object has no attribute 'encode'

During handling of the above exception, another exception occurred:

Traceback (most recent call last):
  File "C:\Users\Серж\Desktop\TopLiga\TopLiga_webapp\TL_VS_solution\Content_prod\logics\modules\gh_push.py", line 42, in gh_push
    auth = Auth.Token(token)    # using an access token
  File "C:\Users\Серж\AppData\Local\Programs\Python\Python310\lib\site-packages\github\Auth.py", line 117, in __init__
    assert isinstance(token, str)
AssertionError

During handling of the above exception, another exception occurred:

Traceback (most recent call last):
  File "C:\Users\Серж\Desktop\TopLiga\TopLiga_webapp\TL_VS_solution\Content_prod\logics\modules\bug_mail.py", line 25, in bug_mail
    s.login(sender, password)
  File "C:\Users\Серж\AppData\Local\Programs\Python\Python310\lib\smtplib.py", line 739, in login
    (code, resp) = self.auth(
  File "C:\Users\Серж\AppData\Local\Programs\Python\Python310\lib\smtplib.py", line 652, in auth
    authobject(challenge).encode('ascii'), eol='')
AttributeError: 'NoneType' object has no attribute 'encode'

During handling of the above exception, another exception occurred:

Traceback (most recent call last):
  File "C:\Users\Серж\Desktop\TopLiga\TopLiga_webapp\TL_VS_solution\Content_prod\logics\modules\gh_push.py", line 42, in gh_push
    auth = Auth.Token(token)    # using an access token
  File "C:\Users\Серж\AppData\Local\Programs\Python\Python310\lib\site-packages\github\Auth.py", line 117, in __init__
    assert isinstance(token, str)
AssertionError

During handling of the above exception, another exception occurred:

Traceback (most recent call last):
  File "C:\Users\Серж\Desktop\TopLiga\TopLiga_webapp\TL_VS_solution\Content_prod\logics\modules\bug_mail.py", line 25, in bug_mail
    s.login(sender, password)
  File "C:\Users\Серж\AppData\Local\Programs\Python\Python310\lib\smtplib.py", line 739, in login
    (code, resp) = self.auth(
  File "C:\Users\Серж\AppData\Local\Programs\Python\Python310\lib\smtplib.py", line 652, in auth
    authobject(challenge).encode('ascii'), eol='')
AttributeError: 'NoneType' object has no attribute 'encode'

During handling of the above exception, another exception occurred:

Traceback (most recent call last):
  File "C:\Users\Серж\Desktop\TopLiga\TopLiga_webapp\TL_VS_solution\Content_prod\logics\modules\gh_push.py", line 42, in gh_push
    auth = Auth.Token(token)    # using an access token
  File "C:\Users\Серж\AppData\Local\Programs\Python\Python310\lib\site-packages\github\Auth.py", line 117, in __init__
    assert isinstance(token, str)
AssertionError

During handling of the above exception, another exception occurred:

Traceback (most recent call last):
  File "C:\Users\Серж\Desktop\TopLiga\TopLiga_webapp\TL_VS_solution\Content_prod\logics\modules\bug_mail.py", line 25, in bug_mail
    s.login(sender, password)
  File "C:\Users\Серж\AppData\Local\Programs\Python\Python310\lib\smtplib.py", line 739, in login
    (code, resp) = self.auth(
  File "C:\Users\Серж\AppData\Local\Programs\Python\Python310\lib\smtplib.py", line 652, in auth
    authobject(challenge).encode('ascii'), eol='')
AttributeError: 'NoneType' object has no attribute 'encode'

During handling of the above exception, another exception occurred:

Traceback (most recent call last):
  File "C:\Users\Серж\Desktop\TopLiga\TopLiga_webapp\TL_VS_solution\Content_prod\logics\modules\gh_push.py", line 42, in gh_push
    auth = Auth.Token(token)    # using an access token
  File "C:\Users\Серж\AppData\Local\Programs\Python\Python310\lib\site-packages\github\Auth.py", line 117, in __init__
    assert isinstance(token, str)
AssertionError

During handling of the above exception, another exception occurred:

Traceback (most recent call last):
  File "C:\Users\Серж\Desktop\TopLiga\TopLiga_webapp\TL_VS_solution\Content_prod\logics\modules\bug_mail.py", line 25, in bug_mail
    s.login(sender, password)
  File "C:\Users\Серж\AppData\Local\Programs\Python\Python310\lib\smtplib.py", line 739, in login
    (code, resp) = self.auth(
  File "C:\Users\Серж\AppData\Local\Programs\Python\Python310\lib\smtplib.py", line 652, in auth
    authobject(challenge).encode('ascii'), eol='')
AttributeError: 'NoneType' object has no attribute 'encode'

During handling of the above exception, another exception occurred:

Traceback (most recent call last):
  File "C:\Users\Серж\Desktop\TopLiga\TopLiga_webapp\TL_VS_solution\Content_prod\logics\modules\gh_push.py", line 42, in gh_push
    auth = Auth.Token(token)    # using an access token
  File "C:\Users\Серж\AppData\Local\Programs\Python\Python310\lib\site-packages\github\Auth.py", line 117, in __init__
    assert isinstance(token, str)
AssertionError

During handling of the above exception, another exception occurred:

Traceback (most recent call last):
  File "C:\Users\Серж\Desktop\TopLiga\TopLiga_webapp\TL_VS_solution\Content_prod\logics\modules\bug_mail.py", line 25, in bug_mail
    s.login(sender, password)
  File "C:\Users\Серж\AppData\Local\Programs\Python\Python310\lib\smtplib.py", line 739, in login
    (code, resp) = self.auth(
  File "C:\Users\Серж\AppData\Local\Programs\Python\Python310\lib\smtplib.py", line 652, in auth
    authobject(challenge).encode('ascii'), eol='')
AttributeError: 'NoneType' object has no attribute 'encode'

During handling of the above exception, another exception occurred:

Traceback (most recent call last):
  File "C:\Users\Серж\Desktop\TopLiga\TopLiga_webapp\TL_VS_solution\Content_prod\logics\modules\gh_push.py", line 42, in gh_push
    auth = Auth.Token(token)    # using an access token
  File "C:\Users\Серж\AppData\Local\Programs\Python\Python310\lib\site-packages\github\Auth.py", line 117, in __init__
    assert isinstance(token, str)
AssertionError

During handling of the above exception, another exception occurred:

Traceback (most recent call last):
  File "C:\Users\Серж\Desktop\TopLiga\TopLiga_webapp\TL_VS_solution\Content_prod\logics\modules\bug_mail.py", line 25, in bug_mail
    s.login(sender, password)
  File "C:\Users\Серж\AppData\Local\Programs\Python\Python310\lib\smtplib.py", line 739, in login
    (code, resp) = self.auth(
  File "C:\Users\Серж\AppData\Local\Programs\Python\Python310\lib\smtplib.py", line 652, in auth
    authobject(challenge).encode('ascii'), eol='')
AttributeError: 'NoneType' object has no attribute 'encode'

During handling of the above exception, another exception occurred:

Traceback (most recent call last):
  File "C:\Users\Серж\Desktop\TopLiga\TopLiga_webapp\TL_VS_solution\Content_prod\logics\modules\gh_push.py", line 42, in gh_push
    auth = Auth.Token(token)    # using an access token
  File "C:\Users\Серж\AppData\Local\Programs\Python\Python310\lib\site-packages\github\Auth.py", line 117, in __init__
    assert isinstance(token, str)
AssertionError

During handling of the above exception, another exception occurred:

Traceback (most recent call last):
  File "C:\Users\Серж\Desktop\TopLiga\TopLiga_webapp\TL_VS_solution\Content_prod\logics\modules\bug_mail.py", line 25, in bug_mail
    s.login(sender, password)
  File "C:\Users\Серж\AppData\Local\Programs\Python\Python310\lib\smtplib.py", line 739, in login
    (code, resp) = self.auth(
  File "C:\Users\Серж\AppData\Local\Programs\Python\Python310\lib\smtplib.py", line 652, in auth
    authobject(challenge).encode('ascii'), eol='')
AttributeError: 'NoneType' object has no attribute 'encode'

During handling of the above exception, another exception occurred:

Traceback (most recent call last):
  File "C:\Users\Серж\Desktop\TopLiga\TopLiga_webapp\TL_VS_solution\Content_prod\logics\modules\gh_push.py", line 42, in gh_push
    auth = Auth.Token(token)    # using an access token
  File "C:\Users\Серж\AppData\Local\Programs\Python\Python310\lib\site-packages\github\Auth.py", line 117, in __init__
    assert isinstance(token, str)
AssertionError

During handling of the above exception, another exception occurred:

Traceback (most recent call last):
  File "C:\Users\Серж\Desktop\TopLiga\TopLiga_webapp\TL_VS_solution\Content_prod\logics\modules\bug_mail.py", line 25, in bug_mail
    s.login(sender, password)
  File "C:\Users\Серж\AppData\Local\Programs\Python\Python310\lib\smtplib.py", line 739, in login
    (code, resp) = self.auth(
  File "C:\Users\Серж\AppData\Local\Programs\Python\Python310\lib\smtplib.py", line 652, in auth
    authobject(challenge).encode('ascii'), eol='')
AttributeError: 'NoneType' object has no attribute 'encode'

During handling of the above exception, another exception occurred:

Traceback (most recent call last):
  File "C:\Users\Серж\Desktop\TopLiga\TopLiga_webapp\TL_VS_solution\Content_prod\logics\modules\gh_push.py", line 42, in gh_push
    auth = Auth.Token(token)    # using an access token
  File "C:\Users\Серж\AppData\Local\Programs\Python\Python310\lib\site-packages\github\Auth.py", line 117, in __init__
    assert isinstance(token, str)
AssertionError

During handling of the above exception, another exception occurred:

Traceback (most recent call last):
  File "C:\Users\Серж\Desktop\TopLiga\TopLiga_webapp\TL_VS_solution\Content_prod\logics\modules\bug_mail.py", line 25, in bug_mail
    s.login(sender, password)
  File "C:\Users\Серж\AppData\Local\Programs\Python\Python310\lib\smtplib.py", line 739, in login
    (code, resp) = self.auth(
  File "C:\Users\Серж\AppData\Local\Programs\Python\Python310\lib\smtplib.py", line 652, in auth
    authobject(challenge).encode('ascii'), eol='')
AttributeError: 'NoneType' object has no attribute 'encode'

During handling of the above exception, another exception occurred:

Traceback (most recent call last):
  File "C:\Users\Серж\Desktop\TopLiga\TopLiga_webapp\TL_VS_solution\Content_prod\logics\modules\gh_push.py", line 42, in gh_push
    auth = Auth.Token(token)    # using an access token
  File "C:\Users\Серж\AppData\Local\Programs\Python\Python310\lib\site-packages\github\Auth.py", line 117, in __init__
    assert isinstance(token, str)
AssertionError

During handling of the above exception, another exception occurred:

Traceback (most recent call last):
  File "C:\Users\Серж\Desktop\TopLiga\TopLiga_webapp\TL_VS_solution\Content_prod\logics\modules\bug_mail.py", line 25, in bug_mail
    s.login(sender, password)
  File "C:\Users\Серж\AppData\Local\Programs\Python\Python310\lib\smtplib.py", line 739, in login
    (code, resp) = self.auth(
  File "C:\Users\Серж\AppData\Local\Programs\Python\Python310\lib\smtplib.py", line 652, in auth
    authobject(challenge).encode('ascii'), eol='')
AttributeError: 'NoneType' object has no attribute 'encode'

During handling of the above exception, another exception occurred:

Traceback (most recent call last):
  File "C:\Users\Серж\Desktop\TopLiga\TopLiga_webapp\TL_VS_solution\Content_prod\logics\modules\gh_push.py", line 42, in gh_push
    auth = Auth.Token(token)    # using an access token
  File "C:\Users\Серж\AppData\Local\Programs\Python\Python310\lib\site-packages\github\Auth.py", line 117, in __init__
    assert isinstance(token, str)
AssertionError

During handling of the above exception, another exception occurred:

Traceback (most recent call last):
  File "C:\Users\Серж\Desktop\TopLiga\TopLiga_webapp\TL_VS_solution\Content_prod\logics\modules\bug_mail.py", line 25, in bug_mail
    s.login(sender, password)
  File "C:\Users\Серж\AppData\Local\Programs\Python\Python310\lib\smtplib.py", line 739, in login
    (code, resp) = self.auth(
  File "C:\Users\Серж\AppData\Local\Programs\Python\Python310\lib\smtplib.py", line 652, in auth
    authobject(challenge).encode('ascii'), eol='')
AttributeError: 'NoneType' object has no attribute 'encode'

During handling of the above exception, another exception occurred:

Traceback (most recent call last):
  File "C:\Users\Серж\Desktop\TopLiga\TopLiga_webapp\TL_VS_solution\Content_prod\logics\modules\gh_push.py", line 42, in gh_push
    auth = Auth.Token(token)    # using an access token
  File "C:\Users\Серж\AppData\Local\Programs\Python\Python310\lib\site-packages\github\Auth.py", line 117, in __init__
    assert isinstance(token, str)
AssertionError

During handling of the above exception, another exception occurred:

Traceback (most recent call last):
  File "C:\Users\Серж\Desktop\TopLiga\TopLiga_webapp\TL_VS_solution\Content_prod\logics\modules\bug_mail.py", line 25, in bug_mail
    s.login(sender, password)
  File "C:\Users\Серж\AppData\Local\Programs\Python\Python310\lib\smtplib.py", line 739, in login
    (code, resp) = self.auth(
  File "C:\Users\Серж\AppData\Local\Programs\Python\Python310\lib\smtplib.py", line 652, in auth
    authobject(challenge).encode('ascii'), eol='')
AttributeError: 'NoneType' object has no attribute 'encode'

During handling of the above exception, another exception occurred:

Traceback (most recent call last):
  File "C:\Users\Серж\Desktop\TopLiga\TopLiga_webapp\TL_VS_solution\Content_prod\logics\modules\gh_push.py", line 42, in gh_push
    auth = Auth.Token(token)    # using an access token
  File "C:\Users\Серж\AppData\Local\Programs\Python\Python310\lib\site-packages\github\Auth.py", line 117, in __init__
    assert isinstance(token, str)
AssertionError

During handling of the above exception, another exception occurred:

Traceback (most recent call last):
  File "C:\Users\Серж\Desktop\TopLiga\TopLiga_webapp\TL_VS_solution\Content_prod\logics\modules\bug_mail.py", line 25, in bug_mail
    s.login(sender, password)
  File "C:\Users\Серж\AppData\Local\Programs\Python\Python310\lib\smtplib.py", line 739, in login
    (code, resp) = self.auth(
  File "C:\Users\Серж\AppData\Local\Programs\Python\Python310\lib\smtplib.py", line 652, in auth
    authobject(challenge).encode('ascii'), eol='')
AttributeError: 'NoneType' object has no attribute 'encode'

During handling of the above exception, another exception occurred:

Traceback (most recent call last):
  File "C:\Users\Серж\Desktop\TopLiga\TopLiga_webapp\TL_VS_solution\Content_prod\logics\modules\gh_push.py", line 42, in gh_push
    auth = Auth.Token(token)    # using an access token
  File "C:\Users\Серж\AppData\Local\Programs\Python\Python310\lib\site-packages\github\Auth.py", line 117, in __init__
    assert isinstance(token, str)
AssertionError

During handling of the above exception, another exception occurred:

Traceback (most recent call last):
  File "C:\Users\Серж\Desktop\TopLiga\TopLiga_webapp\TL_VS_solution\Content_prod\logics\modules\bug_mail.py", line 25, in bug_mail
    s.login(sender, password)
  File "C:\Users\Серж\AppData\Local\Programs\Python\Python310\lib\smtplib.py", line 739, in login
    (code, resp) = self.auth(
  File "C:\Users\Серж\AppData\Local\Programs\Python\Python310\lib\smtplib.py", line 652, in auth
    authobject(challenge).encode('ascii'), eol='')
AttributeError: 'NoneType' object has no attribute 'encode'

During handling of the above exception, another exception occurred:

Traceback (most recent call last):
  File "C:\Users\Серж\Desktop\TopLiga\TopLiga_webapp\TL_VS_solution\Content_prod\logics\modules\gh_push.py", line 42, in gh_push
    auth = Auth.Token(token)    # using an access token
  File "C:\Users\Серж\AppData\Local\Programs\Python\Python310\lib\site-packages\github\Auth.py", line 117, in __init__
    assert isinstance(token, str)
AssertionError

During handling of the above exception, another exception occurred:

Traceback (most recent call last):
  File "C:\Users\Серж\Desktop\TopLiga\TopLiga_webapp\TL_VS_solution\Content_prod\logics\modules\bug_mail.py", line 25, in bug_mail
    s.login(sender, password)
  File "C:\Users\Серж\AppData\Local\Programs\Python\Python310\lib\smtplib.py", line 739, in login
    (code, resp) = self.auth(
  File "C:\Users\Серж\AppData\Local\Programs\Python\Python310\lib\smtplib.py", line 652, in auth
    authobject(challenge).encode('ascii'), eol='')
AttributeError: 'NoneType' object has no attribute 'encode'

During handling of the above exception, another exception occurred:

Traceback (most recent call last):
  File "C:\Users\Серж\Desktop\TopLiga\TopLiga_webapp\TL_VS_solution\Content_prod\logics\modules\gh_push.py", line 42, in gh_push
    auth = Auth.Token(token)    # using an access token
  File "C:\Users\Серж\AppData\Local\Programs\Python\Python310\lib\site-packages\github\Auth.py", line 117, in __init__
    assert isinstance(token, str)
AssertionError

During handling of the above exception, another exception occurred:

Traceback (most recent call last):
  File "C:\Users\Серж\Desktop\TopLiga\TopLiga_webapp\TL_VS_solution\Content_prod\logics\modules\bug_mail.py", line 25, in bug_mail
    s.login(sender, password)
  File "C:\Users\Серж\AppData\Local\Programs\Python\Python310\lib\smtplib.py", line 739, in login
    (code, resp) = self.auth(
  File "C:\Users\Серж\AppData\Local\Programs\Python\Python310\lib\smtplib.py", line 652, in auth
    authobject(challenge).encode('ascii'), eol='')
AttributeError: 'NoneType' object has no attribute 'encode'

During handling of the above exception, another exception occurred:

Traceback (most recent call last):
  File "C:\Users\Серж\Desktop\TopLiga\TopLiga_webapp\TL_VS_solution\Content_prod\logics\modules\gh_push.py", line 42, in gh_push
    auth = Auth.Token(token)    # using an access token
  File "C:\Users\Серж\AppData\Local\Programs\Python\Python310\lib\site-packages\github\Auth.py", line 117, in __init__
    assert isinstance(token, str)
AssertionError

During handling of the above exception, another exception occurred:

Traceback (most recent call last):
  File "C:\Users\Серж\Desktop\TopLiga\TopLiga_webapp\TL_VS_solution\Content_prod\logics\modules\bug_mail.py", line 25, in bug_mail
    s.login(sender, password)
  File "C:\Users\Серж\AppData\Local\Programs\Python\Python310\lib\smtplib.py", line 739, in login
    (code, resp) = self.auth(
  File "C:\Users\Серж\AppData\Local\Programs\Python\Python310\lib\smtplib.py", line 652, in auth
    authobject(challenge).encode('ascii'), eol='')
AttributeError: 'NoneType' object has no attribute 'encode'

During handling of the above exception, another exception occurred:

Traceback (most recent call last):
  File "C:\Users\Серж\Desktop\TopLiga\TopLiga_webapp\TL_VS_solution\Content_prod\logics\modules\gh_push.py", line 42, in gh_push
    auth = Auth.Token(token)    # using an access token
  File "C:\Users\Серж\AppData\Local\Programs\Python\Python310\lib\site-packages\github\Auth.py", line 117, in __init__
    assert isinstance(token, str)
AssertionError

During handling of the above exception, another exception occurred:

Traceback (most recent call last):
  File "C:\Users\Серж\Desktop\TopLiga\TopLiga_webapp\TL_VS_solution\Content_prod\logics\modules\bug_mail.py", line 25, in bug_mail
    s.login(sender, password)
  File "C:\Users\Серж\AppData\Local\Programs\Python\Python310\lib\smtplib.py", line 739, in login
    (code, resp) = self.auth(
  File "C:\Users\Серж\AppData\Local\Programs\Python\Python310\lib\smtplib.py", line 652, in auth
    authobject(challenge).encode('ascii'), eol='')
AttributeError: 'NoneType' object has no attribute 'encode'

During handling of the above exception, another exception occurred:

Traceback (most recent call last):
  File "C:\Users\Серж\Desktop\TopLiga\TopLiga_webapp\TL_VS_solution\Content_prod\logics\modules\gh_push.py", line 42, in gh_push
    auth = Auth.Token(token)    # using an access token
  File "C:\Users\Серж\AppData\Local\Programs\Python\Python310\lib\site-packages\github\Auth.py", line 117, in __init__
    assert isinstance(token, str)
AssertionError

During handling of the above exception, another exception occurred:

Traceback (most recent call last):
  File "C:\Users\Серж\Desktop\TopLiga\TopLiga_webapp\TL_VS_solution\Content_prod\logics\modules\bug_mail.py", line 25, in bug_mail
    s.login(sender, password)
  File "C:\Users\Серж\AppData\Local\Programs\Python\Python310\lib\smtplib.py", line 739, in login
    (code, resp) = self.auth(
  File "C:\Users\Серж\AppData\Local\Programs\Python\Python310\lib\smtplib.py", line 652, in auth
    authobject(challenge).encode('ascii'), eol='')
AttributeError: 'NoneType' object has no attribute 'encode'

During handling of the above exception, another exception occurred:

Traceback (most recent call last):
  File "C:\Users\Серж\Desktop\TopLiga\TopLiga_webapp\TL_VS_solution\Content_prod\logics\modules\gh_push.py", line 42, in gh_push
    auth = Auth.Token(token)    # using an access token
  File "C:\Users\Серж\AppData\Local\Programs\Python\Python310\lib\site-packages\github\Auth.py", line 117, in __init__
    assert isinstance(token, str)
AssertionError

During handling of the above exception, another exception occurred:

Traceback (most recent call last):
  File "C:\Users\Серж\Desktop\TopLiga\TopLiga_webapp\TL_VS_solution\Content_prod\logics\modules\bug_mail.py", line 25, in bug_mail
    s.login(sender, password)
  File "C:\Users\Серж\AppData\Local\Programs\Python\Python310\lib\smtplib.py", line 739, in login
    (code, resp) = self.auth(
  File "C:\Users\Серж\AppData\Local\Programs\Python\Python310\lib\smtplib.py", line 652, in auth
    authobject(challenge).encode('ascii'), eol='')
AttributeError: 'NoneType' object has no attribute 'encode'

During handling of the above exception, another exception occurred:

Traceback (most recent call last):
  File "C:\Users\Серж\Desktop\TopLiga\TopLiga_webapp\TL_VS_solution\Content_prod\logics\modules\gh_push.py", line 42, in gh_push
    auth = Auth.Token(token)    # using an access token
  File "C:\Users\Серж\AppData\Local\Programs\Python\Python310\lib\site-packages\github\Auth.py", line 117, in __init__
    assert isinstance(token, str)
AssertionError

During handling of the above exception, another exception occurred:

Traceback (most recent call last):
  File "C:\Users\Серж\Desktop\TopLiga\TopLiga_webapp\TL_VS_solution\Content_prod\logics\modules\bug_mail.py", line 25, in bug_mail
    s.login(sender, password)
  File "C:\Users\Серж\AppData\Local\Programs\Python\Python310\lib\smtplib.py", line 739, in login
    (code, resp) = self.auth(
  File "C:\Users\Серж\AppData\Local\Programs\Python\Python310\lib\smtplib.py", line 652, in auth
    authobject(challenge).encode('ascii'), eol='')
AttributeError: 'NoneType' object has no attribute 'encode'

During handling of the above exception, another exception occurred:

Traceback (most recent call last):
  File "C:\Users\Серж\Desktop\TopLiga\TopLiga_webapp\TL_VS_solution\Content_prod\logics\modules\gh_push.py", line 42, in gh_push
    auth = Auth.Token(token)    # using an access token
  File "C:\Users\Серж\AppData\Local\Programs\Python\Python310\lib\site-packages\github\Auth.py", line 117, in __init__
    assert isinstance(token, str)
AssertionError

During handling of the above exception, another exception occurred:

Traceback (most recent call last):
  File "C:\Users\Серж\Desktop\TopLiga\TopLiga_webapp\TL_VS_solution\Content_prod\logics\modules\bug_mail.py", line 25, in bug_mail
    s.login(sender, password)
  File "C:\Users\Серж\AppData\Local\Programs\Python\Python310\lib\smtplib.py", line 739, in login
    (code, resp) = self.auth(
  File "C:\Users\Серж\AppData\Local\Programs\Python\Python310\lib\smtplib.py", line 652, in auth
    authobject(challenge).encode('ascii'), eol='')
AttributeError: 'NoneType' object has no attribute 'encode'

During handling of the above exception, another exception occurred:

Traceback (most recent call last):
  File "C:\Users\Серж\Desktop\TopLiga\TopLiga_webapp\TL_VS_solution\Content_prod\logics\modules\gh_push.py", line 42, in gh_push
    auth = Auth.Token(token)    # using an access token
  File "C:\Users\Серж\AppData\Local\Programs\Python\Python310\lib\site-packages\github\Auth.py", line 117, in __init__
    assert isinstance(token, str)
AssertionError

During handling of the above exception, another exception occurred:

Traceback (most recent call last):
  File "C:\Users\Серж\Desktop\TopLiga\TopLiga_webapp\TL_VS_solution\Content_prod\logics\modules\bug_mail.py", line 25, in bug_mail
    s.login(sender, password)
  File "C:\Users\Серж\AppData\Local\Programs\Python\Python310\lib\smtplib.py", line 739, in login
    (code, resp) = self.auth(
  File "C:\Users\Серж\AppData\Local\Programs\Python\Python310\lib\smtplib.py", line 652, in auth
    authobject(challenge).encode('ascii'), eol='')
AttributeError: 'NoneType' object has no attribute 'encode'

During handling of the above exception, another exception occurred:

Traceback (most recent call last):
  File "C:\Users\Серж\Desktop\TopLiga\TopLiga_webapp\TL_VS_solution\Content_prod\logics\modules\gh_push.py", line 42, in gh_push
    auth = Auth.Token(token)    # using an access token
  File "C:\Users\Серж\AppData\Local\Programs\Python\Python310\lib\site-packages\github\Auth.py", line 117, in __init__
    assert isinstance(token, str)
AssertionError

During handling of the above exception, another exception occurred:

Traceback (most recent call last):
  File "C:\Users\Серж\Desktop\TopLiga\TopLiga_webapp\TL_VS_solution\Content_prod\logics\modules\bug_mail.py", line 25, in bug_mail
    s.login(sender, password)
  File "C:\Users\Серж\AppData\Local\Programs\Python\Python310\lib\smtplib.py", line 739, in login
    (code, resp) = self.auth(
  File "C:\Users\Серж\AppData\Local\Programs\Python\Python310\lib\smtplib.py", line 652, in auth
    authobject(challenge).encode('ascii'), eol='')
AttributeError: 'NoneType' object has no attribute 'encode'

During handling of the above exception, another exception occurred:

Traceback (most recent call last):
  File "C:\Users\Серж\Desktop\TopLiga\TopLiga_webapp\TL_VS_solution\Content_prod\logics\modules\gh_push.py", line 42, in gh_push
    auth = Auth.Token(token)    # using an access token
  File "C:\Users\Серж\AppData\Local\Programs\Python\Python310\lib\site-packages\github\Auth.py", line 117, in __init__
    assert isinstance(token, str)
AssertionError

During handling of the above exception, another exception occurred:

Traceback (most recent call last):
  File "C:\Users\Серж\Desktop\TopLiga\TopLiga_webapp\TL_VS_solution\Content_prod\logics\modules\bug_mail.py", line 25, in bug_mail
    s.login(sender, password)
  File "C:\Users\Серж\AppData\Local\Programs\Python\Python310\lib\smtplib.py", line 739, in login
    (code, resp) = self.auth(
  File "C:\Users\Серж\AppData\Local\Programs\Python\Python310\lib\smtplib.py", line 652, in auth
    authobject(challenge).encode('ascii'), eol='')
AttributeError: 'NoneType' object has no attribute 'encode'

During handling of the above exception, another exception occurred:

Traceback (most recent call last):
  File "C:\Users\Серж\Desktop\TopLiga\TopLiga_webapp\TL_VS_solution\Content_prod\logics\modules\gh_push.py", line 42, in gh_push
    auth = Auth.Token(token)    # using an access token
  File "C:\Users\Серж\AppData\Local\Programs\Python\Python310\lib\site-packages\github\Auth.py", line 117, in __init__
    assert isinstance(token, str)
AssertionError

During handling of the above exception, another exception occurred:

Traceback (most recent call last):
  File "C:\Users\Серж\Desktop\TopLiga\TopLiga_webapp\TL_VS_solution\Content_prod\logics\modules\bug_mail.py", line 25, in bug_mail
    s.login(sender, password)
  File "C:\Users\Серж\AppData\Local\Programs\Python\Python310\lib\smtplib.py", line 739, in login
    (code, resp) = self.auth(
  File "C:\Users\Серж\AppData\Local\Programs\Python\Python310\lib\smtplib.py", line 652, in auth
    authobject(challenge).encode('ascii'), eol='')
AttributeError: 'NoneType' object has no attribute 'encode'

During handling of the above exception, another exception occurred:

Traceback (most recent call last):
  File "C:\Users\Серж\Desktop\TopLiga\TopLiga_webapp\TL_VS_solution\Content_prod\logics\modules\gh_push.py", line 42, in gh_push
    auth = Auth.Token(token)    # using an access token
  File "C:\Users\Серж\AppData\Local\Programs\Python\Python310\lib\site-packages\github\Auth.py", line 117, in __init__
    assert isinstance(token, str)
AssertionError

During handling of the above exception, another exception occurred:

Traceback (most recent call last):
  File "C:\Users\Серж\Desktop\TopLiga\TopLiga_webapp\TL_VS_solution\Content_prod\logics\modules\bug_mail.py", line 25, in bug_mail
    s.login(sender, password)
  File "C:\Users\Серж\AppData\Local\Programs\Python\Python310\lib\smtplib.py", line 739, in login
    (code, resp) = self.auth(
  File "C:\Users\Серж\AppData\Local\Programs\Python\Python310\lib\smtplib.py", line 652, in auth
    authobject(challenge).encode('ascii'), eol='')
AttributeError: 'NoneType' object has no attribute 'encode'

During handling of the above exception, another exception occurred:

Traceback (most recent call last):
  File "C:\Users\Серж\Desktop\TopLiga\TopLiga_webapp\TL_VS_solution\Content_prod\logics\modules\gh_push.py", line 42, in gh_push
    auth = Auth.Token(token)    # using an access token
  File "C:\Users\Серж\AppData\Local\Programs\Python\Python310\lib\site-packages\github\Auth.py", line 117, in __init__
    assert isinstance(token, str)
AssertionError

During handling of the above exception, another exception occurred:

Traceback (most recent call last):
  File "C:\Users\Серж\Desktop\TopLiga\TopLiga_webapp\TL_VS_solution\Content_prod\logics\modules\bug_mail.py", line 25, in bug_mail
    s.login(sender, password)
  File "C:\Users\Серж\AppData\Local\Programs\Python\Python310\lib\smtplib.py", line 739, in login
    (code, resp) = self.auth(
  File "C:\Users\Серж\AppData\Local\Programs\Python\Python310\lib\smtplib.py", line 652, in auth
    authobject(challenge).encode('ascii'), eol='')
AttributeError: 'NoneType' object has no attribute 'encode'

During handling of the above exception, another exception occurred:

Traceback (most recent call last):
  File "C:\Users\Серж\Desktop\TopLiga\TopLiga_webapp\TL_VS_solution\Content_prod\logics\modules\gh_push.py", line 42, in gh_push
    auth = Auth.Token(token)    # using an access token
  File "C:\Users\Серж\AppData\Local\Programs\Python\Python310\lib\site-packages\github\Auth.py", line 117, in __init__
    assert isinstance(token, str)
AssertionError

During handling of the above exception, another exception occurred:

Traceback (most recent call last):
  File "C:\Users\Серж\Desktop\TopLiga\TopLiga_webapp\TL_VS_solution\Content_prod\logics\modules\bug_mail.py", line 25, in bug_mail
    s.login(sender, password)
  File "C:\Users\Серж\AppData\Local\Programs\Python\Python310\lib\smtplib.py", line 739, in login
    (code, resp) = self.auth(
  File "C:\Users\Серж\AppData\Local\Programs\Python\Python310\lib\smtplib.py", line 652, in auth
    authobject(challenge).encode('ascii'), eol='')
AttributeError: 'NoneType' object has no attribute 'encode'

During handling of the above exception, another exception occurred:

Traceback (most recent call last):
  File "C:\Users\Серж\Desktop\TopLiga\TopLiga_webapp\TL_VS_solution\Content_prod\logics\modules\gh_push.py", line 42, in gh_push
    auth = Auth.Token(token)    # using an access token
  File "C:\Users\Серж\AppData\Local\Programs\Python\Python310\lib\site-packages\github\Auth.py", line 117, in __init__
    assert isinstance(token, str)
AssertionError

During handling of the above exception, another exception occurred:

Traceback (most recent call last):
  File "C:\Users\Серж\Desktop\TopLiga\TopLiga_webapp\TL_VS_solution\Content_prod\logics\modules\bug_mail.py", line 25, in bug_mail
    s.login(sender, password)
  File "C:\Users\Серж\AppData\Local\Programs\Python\Python310\lib\smtplib.py", line 739, in login
    (code, resp) = self.auth(
  File "C:\Users\Серж\AppData\Local\Programs\Python\Python310\lib\smtplib.py", line 652, in auth
    authobject(challenge).encode('ascii'), eol='')
AttributeError: 'NoneType' object has no attribute 'encode'

During handling of the above exception, another exception occurred:

Traceback (most recent call last):
  File "C:\Users\Серж\Desktop\TopLiga\TopLiga_webapp\TL_VS_solution\Content_prod\logics\modules\gh_push.py", line 42, in gh_push
    auth = Auth.Token(token)    # using an access token
  File "C:\Users\Серж\AppData\Local\Programs\Python\Python310\lib\site-packages\github\Auth.py", line 117, in __init__
    assert isinstance(token, str)
AssertionError

During handling of the above exception, another exception occurred:

Traceback (most recent call last):
  File "C:\Users\Серж\Desktop\TopLiga\TopLiga_webapp\TL_VS_solution\Content_prod\logics\modules\bug_mail.py", line 25, in bug_mail
    s.login(sender, password)
  File "C:\Users\Серж\AppData\Local\Programs\Python\Python310\lib\smtplib.py", line 739, in login
    (code, resp) = self.auth(
  File "C:\Users\Серж\AppData\Local\Programs\Python\Python310\lib\smtplib.py", line 652, in auth
    authobject(challenge).encode('ascii'), eol='')
AttributeError: 'NoneType' object has no attribute 'encode'

During handling of the above exception, another exception occurred:

Traceback (most recent call last):
  File "C:\Users\Серж\Desktop\TopLiga\TopLiga_webapp\TL_VS_solution\Content_prod\logics\modules\gh_push.py", line 42, in gh_push
    auth = Auth.Token(token)    # using an access token
  File "C:\Users\Серж\AppData\Local\Programs\Python\Python310\lib\site-packages\github\Auth.py", line 117, in __init__
    assert isinstance(token, str)
AssertionError

During handling of the above exception, another exception occurred:

Traceback (most recent call last):
  File "C:\Users\Серж\Desktop\TopLiga\TopLiga_webapp\TL_VS_solution\Content_prod\logics\modules\bug_mail.py", line 25, in bug_mail
    s.login(sender, password)
  File "C:\Users\Серж\AppData\Local\Programs\Python\Python310\lib\smtplib.py", line 739, in login
    (code, resp) = self.auth(
  File "C:\Users\Серж\AppData\Local\Programs\Python\Python310\lib\smtplib.py", line 652, in auth
    authobject(challenge).encode('ascii'), eol='')
AttributeError: 'NoneType' object has no attribute 'encode'

During handling of the above exception, another exception occurred:

Traceback (most recent call last):
  File "C:\Users\Серж\Desktop\TopLiga\TopLiga_webapp\TL_VS_solution\Content_prod\logics\modules\gh_push.py", line 42, in gh_push
    auth = Auth.Token(token)    # using an access token
  File "C:\Users\Серж\AppData\Local\Programs\Python\Python310\lib\site-packages\github\Auth.py", line 117, in __init__
    assert isinstance(token, str)
AssertionError

During handling of the above exception, another exception occurred:

Traceback (most recent call last):
  File "C:\Users\Серж\Desktop\TopLiga\TopLiga_webapp\TL_VS_solution\Content_prod\logics\modules\bug_mail.py", line 25, in bug_mail
    s.login(sender, password)
  File "C:\Users\Серж\AppData\Local\Programs\Python\Python310\lib\smtplib.py", line 739, in login
    (code, resp) = self.auth(
  File "C:\Users\Серж\AppData\Local\Programs\Python\Python310\lib\smtplib.py", line 652, in auth
    authobject(challenge).encode('ascii'), eol='')
AttributeError: 'NoneType' object has no attribute 'encode'

During handling of the above exception, another exception occurred:

Traceback (most recent call last):
  File "C:\Users\Серж\Desktop\TopLiga\TopLiga_webapp\TL_VS_solution\Content_prod\logics\modules\gh_push.py", line 42, in gh_push
    auth = Auth.Token(token)    # using an access token
  File "C:\Users\Серж\AppData\Local\Programs\Python\Python310\lib\site-packages\github\Auth.py", line 117, in __init__
    assert isinstance(token, str)
AssertionError

During handling of the above exception, another exception occurred:

Traceback (most recent call last):
  File "C:\Users\Серж\Desktop\TopLiga\TopLiga_webapp\TL_VS_solution\Content_prod\logics\modules\bug_mail.py", line 25, in bug_mail
    s.login(sender, password)
  File "C:\Users\Серж\AppData\Local\Programs\Python\Python310\lib\smtplib.py", line 739, in login
    (code, resp) = self.auth(
  File "C:\Users\Серж\AppData\Local\Programs\Python\Python310\lib\smtplib.py", line 652, in auth
    authobject(challenge).encode('ascii'), eol='')
AttributeError: 'NoneType' object has no attribute 'encode'

During handling of the above exception, another exception occurred:

Traceback (most recent call last):
  File "C:\Users\Серж\Desktop\TopLiga\TopLiga_webapp\TL_VS_solution\Content_prod\logics\modules\gh_push.py", line 42, in gh_push
    auth = Auth.Token(token)    # using an access token
  File "C:\Users\Серж\AppData\Local\Programs\Python\Python310\lib\site-packages\github\Auth.py", line 117, in __init__
    assert isinstance(token, str)
AssertionError

During handling of the above exception, another exception occurred:

Traceback (most recent call last):
  File "C:\Users\Серж\Desktop\TopLiga\TopLiga_webapp\TL_VS_solution\Content_prod\logics\modules\bug_mail.py", line 25, in bug_mail
    s.login(sender, password)
  File "C:\Users\Серж\AppData\Local\Programs\Python\Python310\lib\smtplib.py", line 739, in login
    (code, resp) = self.auth(
  File "C:\Users\Серж\AppData\Local\Programs\Python\Python310\lib\smtplib.py", line 652, in auth
    authobject(challenge).encode('ascii'), eol='')
AttributeError: 'NoneType' object has no attribute 'encode'

During handling of the above exception, another exception occurred:

Traceback (most recent call last):
  File "C:\Users\Серж\Desktop\TopLiga\TopLiga_webapp\TL_VS_solution\Content_prod\logics\modules\gh_push.py", line 42, in gh_push
    auth = Auth.Token(token)    # using an access token
  File "C:\Users\Серж\AppData\Local\Programs\Python\Python310\lib\site-packages\github\Auth.py", line 117, in __init__
    assert isinstance(token, str)
AssertionError

During handling of the above exception, another exception occurred:

Traceback (most recent call last):
  File "C:\Users\Серж\Desktop\TopLiga\TopLiga_webapp\TL_VS_solution\Content_prod\logics\modules\bug_mail.py", line 25, in bug_mail
    s.login(sender, password)
  File "C:\Users\Серж\AppData\Local\Programs\Python\Python310\lib\smtplib.py", line 739, in login
    (code, resp) = self.auth(
  File "C:\Users\Серж\AppData\Local\Programs\Python\Python310\lib\smtplib.py", line 652, in auth
    authobject(challenge).encode('ascii'), eol='')
AttributeError: 'NoneType' object has no attribute 'encode'

During handling of the above exception, another exception occurred:

Traceback (most recent call last):
  File "C:\Users\Серж\Desktop\TopLiga\TopLiga_webapp\TL_VS_solution\Content_prod\logics\modules\gh_push.py", line 42, in gh_push
    auth = Auth.Token(token)    # using an access token
  File "C:\Users\Серж\AppData\Local\Programs\Python\Python310\lib\site-packages\github\Auth.py", line 117, in __init__
    assert isinstance(token, str)
AssertionError

During handling of the above exception, another exception occurred:

Traceback (most recent call last):
  File "C:\Users\Серж\Desktop\TopLiga\TopLiga_webapp\TL_VS_solution\Content_prod\logics\modules\bug_mail.py", line 25, in bug_mail
    s.login(sender, password)
  File "C:\Users\Серж\AppData\Local\Programs\Python\Python310\lib\smtplib.py", line 739, in login
    (code, resp) = self.auth(
  File "C:\Users\Серж\AppData\Local\Programs\Python\Python310\lib\smtplib.py", line 652, in auth
    authobject(challenge).encode('ascii'), eol='')
AttributeError: 'NoneType' object has no attribute 'encode'

During handling of the above exception, another exception occurred:

Traceback (most recent call last):
  File "C:\Users\Серж\Desktop\TopLiga\TopLiga_webapp\TL_VS_solution\Content_prod\logics\modules\gh_push.py", line 42, in gh_push
    auth = Auth.Token(token)    # using an access token
  File "C:\Users\Серж\AppData\Local\Programs\Python\Python310\lib\site-packages\github\Auth.py", line 117, in __init__
    assert isinstance(token, str)
AssertionError

During handling of the above exception, another exception occurred:

Traceback (most recent call last):
  File "C:\Users\Серж\Desktop\TopLiga\TopLiga_webapp\TL_VS_solution\Content_prod\logics\modules\bug_mail.py", line 25, in bug_mail
    s.login(sender, password)
  File "C:\Users\Серж\AppData\Local\Programs\Python\Python310\lib\smtplib.py", line 739, in login
    (code, resp) = self.auth(
  File "C:\Users\Серж\AppData\Local\Programs\Python\Python310\lib\smtplib.py", line 652, in auth
    authobject(challenge).encode('ascii'), eol='')
AttributeError: 'NoneType' object has no attribute 'encode'

During handling of the above exception, another exception occurred:

Traceback (most recent call last):
  File "C:\Users\Серж\Desktop\TopLiga\TopLiga_webapp\TL_VS_solution\Content_prod\logics\modules\gh_push.py", line 42, in gh_push
    auth = Auth.Token(token)    # using an access token
  File "C:\Users\Серж\AppData\Local\Programs\Python\Python310\lib\site-packages\github\Auth.py", line 117, in __init__
    assert isinstance(token, str)
AssertionError

During handling of the above exception, another exception occurred:

Traceback (most recent call last):
  File "C:\Users\Серж\Desktop\TopLiga\TopLiga_webapp\TL_VS_solution\Content_prod\logics\modules\bug_mail.py", line 25, in bug_mail
    s.login(sender, password)
  File "C:\Users\Серж\AppData\Local\Programs\Python\Python310\lib\smtplib.py", line 739, in login
    (code, resp) = self.auth(
  File "C:\Users\Серж\AppData\Local\Programs\Python\Python310\lib\smtplib.py", line 652, in auth
    authobject(challenge).encode('ascii'), eol='')
AttributeError: 'NoneType' object has no attribute 'encode'

During handling of the above exception, another exception occurred:

Traceback (most recent call last):
  File "C:\Users\Серж\Desktop\TopLiga\TopLiga_webapp\TL_VS_solution\Content_prod\logics\modules\gh_push.py", line 42, in gh_push
    auth = Auth.Token(token)    # using an access token
  File "C:\Users\Серж\AppData\Local\Programs\Python\Python310\lib\site-packages\github\Auth.py", line 117, in __init__
    assert isinstance(token, str)
AssertionError

During handling of the above exception, another exception occurred:

Traceback (most recent call last):
  File "C:\Users\Серж\Desktop\TopLiga\TopLiga_webapp\TL_VS_solution\Content_prod\logics\modules\bug_mail.py", line 25, in bug_mail
    s.login(sender, password)
  File "C:\Users\Серж\AppData\Local\Programs\Python\Python310\lib\smtplib.py", line 739, in login
    (code, resp) = self.auth(
  File "C:\Users\Серж\AppData\Local\Programs\Python\Python310\lib\smtplib.py", line 652, in auth
    authobject(challenge).encode('ascii'), eol='')
AttributeError: 'NoneType' object has no attribute 'encode'

During handling of the above exception, another exception occurred:

Traceback (most recent call last):
  File "C:\Users\Серж\Desktop\TopLiga\TopLiga_webapp\TL_VS_solution\Content_prod\logics\modules\gh_push.py", line 42, in gh_push
    auth = Auth.Token(token)    # using an access token
  File "C:\Users\Серж\AppData\Local\Programs\Python\Python310\lib\site-packages\github\Auth.py", line 117, in __init__
    assert isinstance(token, str)
AssertionError

During handling of the above exception, another exception occurred:

Traceback (most recent call last):
  File "C:\Users\Серж\Desktop\TopLiga\TopLiga_webapp\TL_VS_solution\Content_prod\logics\modules\bug_mail.py", line 25, in bug_mail
    s.login(sender, password)
  File "C:\Users\Серж\AppData\Local\Programs\Python\Python310\lib\smtplib.py", line 739, in login
    (code, resp) = self.auth(
  File "C:\Users\Серж\AppData\Local\Programs\Python\Python310\lib\smtplib.py", line 652, in auth
    authobject(challenge).encode('ascii'), eol='')
AttributeError: 'NoneType' object has no attribute 'encode'

During handling of the above exception, another exception occurred:

Traceback (most recent call last):
  File "C:\Users\Серж\Desktop\TopLiga\TopLiga_webapp\TL_VS_solution\Content_prod\logics\modules\gh_push.py", line 42, in gh_push
    auth = Auth.Token(token)    # using an access token
  File "C:\Users\Серж\AppData\Local\Programs\Python\Python310\lib\site-packages\github\Auth.py", line 117, in __init__
    assert isinstance(token, str)
AssertionError

During handling of the above exception, another exception occurred:

Traceback (most recent call last):
  File "C:\Users\Серж\Desktop\TopLiga\TopLiga_webapp\TL_VS_solution\Content_prod\logics\modules\bug_mail.py", line 25, in bug_mail
    s.login(sender, password)
  File "C:\Users\Серж\AppData\Local\Programs\Python\Python310\lib\smtplib.py", line 739, in login
    (code, resp) = self.auth(
  File "C:\Users\Серж\AppData\Local\Programs\Python\Python310\lib\smtplib.py", line 652, in auth
    authobject(challenge).encode('ascii'), eol='')
AttributeError: 'NoneType' object has no attribute 'encode'

During handling of the above exception, another exception occurred:

Traceback (most recent call last):
  File "C:\Users\Серж\Desktop\TopLiga\TopLiga_webapp\TL_VS_solution\Content_prod\logics\modules\gh_push.py", line 42, in gh_push
    auth = Auth.Token(token)    # using an access token
  File "C:\Users\Серж\AppData\Local\Programs\Python\Python310\lib\site-packages\github\Auth.py", line 117, in __init__
    assert isinstance(token, str)
AssertionError

During handling of the above exception, another exception occurred:

Traceback (most recent call last):
  File "C:\Users\Серж\Desktop\TopLiga\TopLiga_webapp\TL_VS_solution\Content_prod\logics\modules\bug_mail.py", line 25, in bug_mail
    s.login(sender, password)
  File "C:\Users\Серж\AppData\Local\Programs\Python\Python310\lib\smtplib.py", line 739, in login
    (code, resp) = self.auth(
  File "C:\Users\Серж\AppData\Local\Programs\Python\Python310\lib\smtplib.py", line 652, in auth
    authobject(challenge).encode('ascii'), eol='')
AttributeError: 'NoneType' object has no attribute 'encode'

During handling of the above exception, another exception occurred:

Traceback (most recent call last):
  File "C:\Users\Серж\Desktop\TopLiga\TopLiga_webapp\TL_VS_solution\Content_prod\logics\modules\gh_push.py", line 42, in gh_push
    auth = Auth.Token(token)    # using an access token
  File "C:\Users\Серж\AppData\Local\Programs\Python\Python310\lib\site-packages\github\Auth.py", line 117, in __init__
    assert isinstance(token, str)
AssertionError

During handling of the above exception, another exception occurred:

Traceback (most recent call last):
  File "C:\Users\Серж\Desktop\TopLiga\TopLiga_webapp\TL_VS_solution\Content_prod\logics\modules\bug_mail.py", line 25, in bug_mail
    s.login(sender, password)
  File "C:\Users\Серж\AppData\Local\Programs\Python\Python310\lib\smtplib.py", line 739, in login
    (code, resp) = self.auth(
  File "C:\Users\Серж\AppData\Local\Programs\Python\Python310\lib\smtplib.py", line 652, in auth
    authobject(challenge).encode('ascii'), eol='')
AttributeError: 'NoneType' object has no attribute 'encode'

During handling of the above exception, another exception occurred:

Traceback (most recent call last):
  File "C:\Users\Серж\Desktop\TopLiga\TopLiga_webapp\TL_VS_solution\Content_prod\logics\modules\gh_push.py", line 42, in gh_push
    auth = Auth.Token(token)    # using an access token
  File "C:\Users\Серж\AppData\Local\Programs\Python\Python310\lib\site-packages\github\Auth.py", line 117, in __init__
    assert isinstance(token, str)
AssertionError

During handling of the above exception, another exception occurred:

Traceback (most recent call last):
  File "C:\Users\Серж\Desktop\TopLiga\TopLiga_webapp\TL_VS_solution\Content_prod\logics\modules\bug_mail.py", line 25, in bug_mail
    s.login(sender, password)
  File "C:\Users\Серж\AppData\Local\Programs\Python\Python310\lib\smtplib.py", line 739, in login
    (code, resp) = self.auth(
  File "C:\Users\Серж\AppData\Local\Programs\Python\Python310\lib\smtplib.py", line 652, in auth
    authobject(challenge).encode('ascii'), eol='')
AttributeError: 'NoneType' object has no attribute 'encode'

During handling of the above exception, another exception occurred:

Traceback (most recent call last):
  File "C:\Users\Серж\Desktop\TopLiga\TopLiga_webapp\TL_VS_solution\Content_prod\logics\modules\gh_push.py", line 42, in gh_push
    auth = Auth.Token(token)    # using an access token
  File "C:\Users\Серж\AppData\Local\Programs\Python\Python310\lib\site-packages\github\Auth.py", line 117, in __init__
    assert isinstance(token, str)
AssertionError

During handling of the above exception, another exception occurred:

Traceback (most recent call last):
  File "C:\Users\Серж\Desktop\TopLiga\TopLiga_webapp\TL_VS_solution\Content_prod\logics\modules\bug_mail.py", line 25, in bug_mail
    s.login(sender, password)
  File "C:\Users\Серж\AppData\Local\Programs\Python\Python310\lib\smtplib.py", line 739, in login
    (code, resp) = self.auth(
  File "C:\Users\Серж\AppData\Local\Programs\Python\Python310\lib\smtplib.py", line 652, in auth
    authobject(challenge).encode('ascii'), eol='')
AttributeError: 'NoneType' object has no attribute 'encode'

During handling of the above exception, another exception occurred:

Traceback (most recent call last):
  File "C:\Users\Серж\Desktop\TopLiga\TopLiga_webapp\TL_VS_solution\Content_prod\logics\modules\gh_push.py", line 42, in gh_push
    auth = Auth.Token(token)    # using an access token
  File "C:\Users\Серж\AppData\Local\Programs\Python\Python310\lib\site-packages\github\Auth.py", line 117, in __init__
    assert isinstance(token, str)
AssertionError

During handling of the above exception, another exception occurred:

Traceback (most recent call last):
  File "C:\Users\Серж\Desktop\TopLiga\TopLiga_webapp\TL_VS_solution\Content_prod\logics\modules\bug_mail.py", line 25, in bug_mail
    s.login(sender, password)
  File "C:\Users\Серж\AppData\Local\Programs\Python\Python310\lib\smtplib.py", line 739, in login
    (code, resp) = self.auth(
  File "C:\Users\Серж\AppData\Local\Programs\Python\Python310\lib\smtplib.py", line 652, in auth
    authobject(challenge).encode('ascii'), eol='')
AttributeError: 'NoneType' object has no attribute 'encode'

During handling of the above exception, another exception occurred:

Traceback (most recent call last):
  File "C:\Users\Серж\Desktop\TopLiga\TopLiga_webapp\TL_VS_solution\Content_prod\logics\modules\gh_push.py", line 42, in gh_push
    auth = Auth.Token(token)    # using an access token
  File "C:\Users\Серж\AppData\Local\Programs\Python\Python310\lib\site-packages\github\Auth.py", line 117, in __init__
    assert isinstance(token, str)
AssertionError

During handling of the above exception, another exception occurred:

Traceback (most recent call last):
  File "C:\Users\Серж\Desktop\TopLiga\TopLiga_webapp\TL_VS_solution\Content_prod\logics\modules\bug_mail.py", line 25, in bug_mail
    s.login(sender, password)
  File "C:\Users\Серж\AppData\Local\Programs\Python\Python310\lib\smtplib.py", line 739, in login
    (code, resp) = self.auth(
  File "C:\Users\Серж\AppData\Local\Programs\Python\Python310\lib\smtplib.py", line 652, in auth
    authobject(challenge).encode('ascii'), eol='')
AttributeError: 'NoneType' object has no attribute 'encode'

During handling of the above exception, another exception occurred:

Traceback (most recent call last):
  File "C:\Users\Серж\Desktop\TopLiga\TopLiga_webapp\TL_VS_solution\Content_prod\logics\modules\gh_push.py", line 42, in gh_push
    auth = Auth.Token(token)    # using an access token
  File "C:\Users\Серж\AppData\Local\Programs\Python\Python310\lib\site-packages\github\Auth.py", line 117, in __init__
    assert isinstance(token, str)
AssertionError

During handling of the above exception, another exception occurred:

Traceback (most recent call last):
  File "C:\Users\Серж\Desktop\TopLiga\TopLiga_webapp\TL_VS_solution\Content_prod\logics\modules\bug_mail.py", line 25, in bug_mail
    s.login(sender, password)
  File "C:\Users\Серж\AppData\Local\Programs\Python\Python310\lib\smtplib.py", line 739, in login
    (code, resp) = self.auth(
  File "C:\Users\Серж\AppData\Local\Programs\Python\Python310\lib\smtplib.py", line 652, in auth
    authobject(challenge).encode('ascii'), eol='')
AttributeError: 'NoneType' object has no attribute 'encode'

During handling of the above exception, another exception occurred:

Traceback (most recent call last):
  File "C:\Users\Серж\Desktop\TopLiga\TopLiga_webapp\TL_VS_solution\Content_prod\logics\modules\gh_push.py", line 42, in gh_push
    auth = Auth.Token(token)    # using an access token
  File "C:\Users\Серж\AppData\Local\Programs\Python\Python310\lib\site-packages\github\Auth.py", line 117, in __init__
    assert isinstance(token, str)
AssertionError

During handling of the above exception, another exception occurred:

Traceback (most recent call last):
  File "C:\Users\Серж\Desktop\TopLiga\TopLiga_webapp\TL_VS_solution\Content_prod\logics\modules\bug_mail.py", line 25, in bug_mail
    s.login(sender, password)
  File "C:\Users\Серж\AppData\Local\Programs\Python\Python310\lib\smtplib.py", line 739, in login
    (code, resp) = self.auth(
  File "C:\Users\Серж\AppData\Local\Programs\Python\Python310\lib\smtplib.py", line 652, in auth
    authobject(challenge).encode('ascii'), eol='')
AttributeError: 'NoneType' object has no attribute 'encode'

During handling of the above exception, another exception occurred:

Traceback (most recent call last):
  File "C:\Users\Серж\Desktop\TopLiga\TopLiga_webapp\TL_VS_solution\Content_prod\logics\modules\gh_push.py", line 42, in gh_push
    auth = Auth.Token(token)    # using an access token
  File "C:\Users\Серж\AppData\Local\Programs\Python\Python310\lib\site-packages\github\Auth.py", line 117, in __init__
    assert isinstance(token, str)
AssertionError
